Workbook

Sheet 05C_Governance_Coding_RE
A1: company_id | B1: doc_id | C1: gov_crit_id | D1: doc_id_primary_evidence | E1: score_0_3 | F1: evidence_quote | G1: evidence_location | H1: why_not_higher | I1: coder_confidence | J1: notes
A2: 7 | B2: 37 | C2: GOV_01 | E2: 2 | F2: “centre of competence… ensures rapid knowledge and technology sharing across the company.” | G2: S.3 – Project AI (centre of competence) | H2: Rolle/Einheit und Aufgaben sichtbar; keine Review-/Reporting-Belege. | I2: mittel
A3: 7 | B3: 37 | C3: GOV_02 | E3: 1 | F3: “These will be continuously refined and adapted as required…” | G3: S.1 – continuously refined/adapted | H3: Nur Prozessabsicht; keine Prozessstufen/Trigger/Owner. | I3: mittel | M3: Keine Governance-Deltas.
A4: 7 | B4: 37 | C4: GOV_03 | E4: 2 | F4: “a portfolio tool… D³… portfolio currently spans 400 use cases.” | G4: S.3 – D³ portfolio tool | H4: Konkreter Check-/Inventory-Mechanismus, aber ohne Protokoll-/Output-Nachweis. | I4: mittel | M4: Alle sieben BMW-Governance-Codes und alle sieben Deutsche-Telekom-Governance-Codes stimmen im Re-Coding mit den Pilot-Scores überein.
A5: 7 | B5: 37 | C5: GOV_04 | E5: 0 | I5: hoch | J5: Nicht nachweisbar.
A6: 7 | B6: 37 | C6: GOV_05 | E6: 1 | F6: “increase awareness among its employees… sensitivity when working with AI technologies.” | G6: S.1 – increase awareness | H6: Awareness benannt, aber kein Trainingsprogramm/Pflichtgrad. | I6: niedrig
A7: 7 | B7: 37 | C7: GOV_06 | E7: 0 | I7: hoch | J7: Nicht nachweisbar.
A8: 7 | B8: 37 | C8: GOV_07 | E8: 1 | F8: “will identify, assess, report and mitigate risks…” | G8: S.3 – Accountability (“report… risks”) | H8: Reporting-Absicht ja, aber ohne Empfänger/Frequenz/KPI. | I8: mittel
A9: 15 | B9: 86 | C9: GOV_01 | E9: 2 | F9: “we clarify which initiative or product owner has which responsibilities.”; “Group Compliance Management” | G9: S.3 (product owner); p.12 (Group Compliance Management) | H9: Rollen/Verankerung benannt; Aufgaben grob (responsibilities). | I9: mittel
A10: 15 | B10: 86 | C10: GOV_02 | E10: 1 | F10: “developed and enhanced on grounds of deep analysis and evaluation.” | G10: S.8 – deep analysis/evaluation | H10: Prozessabsicht/Schritt erwähnt; Trigger/Owner nicht vollständig. | I10: mittel
A11: 15 | B11: 86 | C11: GOV_03 | E11: 2 | F11: “stop AI systems at any time (kill switch).”; “In case of inconsistencies, we rather stop the AI system”; “reset… in order to remove false or biased data.” | G11: S.9 (kill switch/stop/reset); p.8 (privacy & security by design) | H11: Konkrete Kontrolltools + „wann“ teils klar („any time“, „in case of inconsistencies“). | I11: mittel
A12: 15 | B12: 86 | C12: GOV_04 | E12: 1 | F12: “transparent, auditable, fair, and fully documented.” | G12: S.8 – “auditable” | H12: Audit/Assessment nur als Eigenschaft erwähnt; keine Audit-Mechanik. | I12: niedrig
A13: 15 | B13: 86 | C13: GOV_05 | E13: 1 | F13: “We will engage in AI and ethics education.” | G13: S.11 – AI and ethics education | H13: Education zugesagt, ohne Programm-/Pflichtdetails. | I13: mittel
A14: 15 | B14: 86 | C14: GOV_06 | I14: hoch | J14: Nicht nachweisbar.
A15: 15 | B15: 86 | C15: GOV_07 | I15: hoch | J15: Nicht nachweisbar.

Sheet 03c_Values_Coding_RE
A1: company_id | B1: doc_id | C1: value_id | D1: value_present | E1: binding_level | F1: binding_justification | G1: evidence_quote | H1: evidence_location | I1: coder_confidence | J1: notes | K1: value_points | N1: POST-HOC Vergleich: Re-Coding vs Pilot-Coding
A2: 7 | B2: 37 | C2: VAL_01 | D2: 1 | E2: 3 | F2: Human oversight inkl. Möglichkeit des menschlichen Overrules | G2: “implements appropriate human monitoring… and considers… humans can overrule algorithmic decisions.” | H2: S.2 – Human agency and oversight | I2: hoch | J2: Klarer Kontroll-/Override-Schritt; stärkste Evidenz im Dokument. | K2: =Tabelle5225[[#This Row],[value_present]]*Tabelle5225[[#This Row],[binding_level]] -> 3 | N2: company_id | O2: value_id | P2: pilot_value_present | Q2: recode_value_present | R2: pilot_binding_level | S2: recode_binding_level | T2: delta_type | U2: change_cause | V2: evidence_anchor_recode
A3: 7 | B3: 37 | C3: VAL_02 | D3: 1 | E3: 1 | F3: Risiken werden identifiziert/bewertet/berichtet/mitigiert | G3: “will identify, assess, report and mitigate risks…” | H3: S.3 – Accountability | I3: Hoch | J3: Verantwortungsprinzip explizit, aber ohne Rollen-/Mechanikanker im Wertesinn. | K3: =Tabelle5225[[#This Row],[value_present]]*Tabelle5225[[#This Row],[binding_level]] -> 1 | N3: 7 | O3: VAL_01 | P3: 1 | Q3: 1 | R3: 1 | S3: 3 | T3: binding | U3: Correction of inconsistent pilot coding | V3: doc 37, S.2 – human monitoring / overrule
A4: 7 | B4: 37 | C4: VAL_03 | D4: 1 | E4: 1 | F4: Transparenz über Einsatz der Technologien + Kommunikation | G4: “aims… open communication where respective technologies are used.” | H4: S.2 – Transparency | I4: Hoch | J4: Disclosure/Offenlegung des AI-Einsatzes. | K4: =Tabelle5225[[#This Row],[value_present]]*Tabelle5225[[#This Row],[binding_level]] -> 1 | N4: 7 | O4: VAL_14 | P4: 1 | Q4: 1 | R4: 1 | S4: 2 | T4: binding | U4: Rule change (expected) | V4: doc 37, S.2 – applicable safety standards
A5: 7 | B5: 37 | C5: VAL_04 | D5: 1 | E5: 1 | F5: Explainability als Ziel bei AI applications | G5: “aims for explainability of AI applications…” | H5: S.2 – Transparency | I5: hoch | J5: Explainability explizit, aber nur Prinzipienniveau. | K5: =Tabelle5225[[#This Row],[value_present]]*Tabelle5225[[#This Row],[binding_level]] -> 1 | N5: 7 | O5: VAL_15 | P5: 1 | Q5: 0 | R5: 1 | S5: — | T5: both | U5: Rule change (expected) | V5: kein eigenständiger ethischer Grenzsatz in doc 37
A6: 7 | B6: 37 | C6: VAL_05 | D6: 1 | E6: 1 | F6: Fairness über Human Dignity; Ziel „fair AI“ | G6: “respects human dignity… sets out to build fair AI applications.” | H6: S.2 – Diversity, non-discrimination and fairness | I6: hoch | J6: Fairness klar, ohne operativen Kontrollschritt. | K6: =Tabelle5225[[#This Row],[value_present]]*Tabelle5225[[#This Row],[binding_level]] -> 1 | N6: 15 | O6: VAL_01 | P6: 1 | Q6: 1 | R6: 2 | S6: 3 | T6: binding | U6: Correction of inconsistent pilot coding | V6: doc 86, S.9 – kill switch
A7: 7 | B7: 37 | C7: VAL_06 | D7: 1 | E7: 1 | F7: Privacy & data security auf AI storage/processing erweitert | G7: “extends its… data privacy and data security measures to cover storage and processing in AI applications.” | H7: S.2 – Privacy and data governance | I7: hoch | J7: KI-bezogener Datenschutz eindeutig. | K7: =Tabelle5225[[#This Row],[value_present]]*Tabelle5225[[#This Row],[binding_level]] -> 1 | N7: 15 | O7: VAL_05 | P7: 1 | Q7: 1 | R7: 1 | S7: 3 | T7: binding | U7: Correction of inconsistent pilot coding | V7: doc 86, S.9 – remove inappropriate data to avoid bias
A8: 7 | B8: 37 | C8: VAL_07 | D8: 1 | E8: 1 | F8: Data security measures im AI-Kontext | G8: “data… security measures… in AI applications.” | H8: S.2 – Privacy and data governance | I8: Hoch | J8: Security-Anker vorhanden, aber nicht weiter operationalisiert. | K8: =Tabelle5225[[#This Row],[value_present]]*Tabelle5225[[#This Row],[binding_level]] -> 1 | N8: 15 | O8: VAL_08 | P8: 1 | Q8: 1 | R8: 2 | S8: 3 | T8: binding | U8: Correction of inconsistent pilot coding | V8: doc 86, S.9 – stop AI system on inconsistencies
A9: 7 | B9: 37 | C9: VAL_08 | D9: 1 | E9: 1 | F9: Safety/Vermeidung unbeabsichtigter Folgen/Errors | G9: “decrease the risk of unintended consequences and errors.” | H9: S.2 – Technical robustness and safety | I9: Hoch | J9: Safety/Harm-Prevention klar, jedoch ohne Prozessschritt. | K9: =Tabelle5225[[#This Row],[value_present]]*Tabelle5225[[#This Row],[binding_level]] -> 1 | N9: 15 | O9: VAL_15 | P9: 1 | Q9: 0 | R9: 1 | S9: — | T9: both | U9: Rule change (expected) | V9: kein ethischer Grenzsatz, nur Responsible-AI-Rhetorik
A10: 7 | B10: 37 | C10: VAL_09 | D10: 1 | E10: 1 | F10: Robustheit/Safety-Standards zur Fehler-/Risiko-Reduktion | G10: “aims to develop robust AI applications and observes the applicable safety standards…” | H10: S.2 – Technical robustness and safety | I10: hoch | J10: Robustheit explizit, aber nicht test-/monitoringbezogen. | K10: =Tabelle5225[[#This Row],[value_present]]*Tabelle5225[[#This Row],[binding_level]] -> 1
A11: 7 | B11: 37 | C11: VAL_10 | D11: 0 | H11: — | I11: hoch | J11: Kein belastbarer Redress-/Contestability-Anker. | K11: =Tabelle5225[[#This Row],[value_present]]*Tabelle5225[[#This Row],[binding_level]] -> 0
A12: 7 | B12: 37 | C12: VAL_11 | D12: 0 | H12: — | I12: hoch | J12: Kein Accessibility-/Teilhabebeleg mit KI-Anker. | K12: =Tabelle5225[[#This Row],[value_present]]*Tabelle5225[[#This Row],[binding_level]] -> 0
A13: 7 | B13: 37 | C13: VAL_12 | D13: 1 | E13: 1 | F13: AI soll Umwelt-/Societal Well-being fördern (inkl. Klima/Umweltschutz) | G13: “goals… human rights and sustainability… climate change and environmental protection.” | H13: S.2 – Environmental and societal well-being | I13: hoch | J13: Umweltbezug explizit. | K13: =Tabelle5225[[#This Row],[value_present]]*Tabelle5225[[#This Row],[binding_level]] -> 1
A14: 7 | B14: 37 | C14: VAL_13 | D14: 1 | E14: 1 | F14: AI soll Well-being von Stakeholdern fördern | G14: “AI applications that promote the well-being of customers, employees and partners.” | H14: S.2 – Environmental and societal well-being | I14: hoch | J14: Konkreter Well-being-/Benefit-Anker. | K14: =Tabelle5225[[#This Row],[value_present]]*Tabelle5225[[#This Row],[binding_level]] -> 1
A15: 7 | B15: 37 | C15: VAL_14 | D15: 1 | E15: 2 | F15: „Applicable safety standards“ als Compliance-Anker (indirekt) | G15: “observes the applicable safety standards…” | H15: S.2 – Technical robustness and safety | I15: Mittel | J15: Standard-/Compliance-Bezug; deontisch stärker als bloßes Statement. | K15: =Tabelle5225[[#This Row],[value_present]]*Tabelle5225[[#This Row],[binding_level]] -> 2
A16: 7 | B16: 37 | C16: VAL_15 | D16: 0 | H16: — | I16: mittel | J16: Nur Ethik-/Responsible-AI-Rhetorik; keine eigenständige ethische Grenze. | K16: =Tabelle5225[[#This Row],[value_present]]*Tabelle5225[[#This Row],[binding_level]] -> 0
A17: 7 | B17: 37 | C17: VAL_16 | D17: 0 | H17: — | I17: hoch | J17: Kein konkreter Data-quality-/Dataset-governance-Anker. | K17: =Tabelle5225[[#This Row],[value_present]]*Tabelle5225[[#This Row],[binding_level]] -> 0
A18: 7 | B18: 37 | C18: VAL_17 | D18: 0 | H18: — | I18: hoch | J18: Kein belastbarer KI-spezifischer IP-/Confidentiality-Anker. | K18: =Tabelle5225[[#This Row],[value_present]]*Tabelle5225[[#This Row],[binding_level]] -> 0
A19: 7 | B19: 37 | C19: VAL_18 | D19: 1 | E19: 1 | F19: Bezug zu Human Rights-Zielen | G19: “aligns with the BMW Group’s goals in the areas of human rights…” | H19: S.2 – Environmental and societal well-being | I19: mittel | J19: Human-rights-Frame explizit genannt. | K19: =Tabelle5225[[#This Row],[value_present]]*Tabelle5225[[#This Row],[binding_level]] -> 1
A20: 15 | B20: 86 | C20: VAL_01 | D20: 1 | E20: 3 | F20: Agency/Choice im Kontext Daten/KI-Interaktion.;Kill switch als konkrete Kontrollmöglichkeit | G20: “they can choose the way of further processing their personal data.”; "stop AI systems at any time (kill switch).” | H20: S.6 (Choice); S.9 (kill switch) | I20: Hoch | J20: Klarer menschlicher Kontroll-/Interventionsschritt. | K20: =Tabelle5225[[#This Row],[value_present]]*Tabelle5225[[#This Row],[binding_level]] -> 3
A21: 15 | B21: 86 | C21: VAL_02 | D21: 1 | E21: 2 | F21: Accountability/Responsibility im KI-Kontext.; Product Owner/Initiative Owner Verantwortlichkeiten werden geklärt | G21: “The human always remains responsible.”; “we clarify which initiative or product owner has which responsibilities.” | H21: S.3 – 1. We are responsible. | I21: hoch | J21: Deutliches Verantwortungsprinzip; keine weitergehende Prozesskopplung. | K21: =Tabelle5225[[#This Row],[value_present]]*Tabelle5225[[#This Row],[binding_level]] -> 2
A22: 15 | B22: 86 | C22: VAL_03 | D22: 1 | E22: 2 | F22: Transparenz/Disclosure eindeutig. | G22: “In no case we hide it when the customer’s counterpart is an AI.” | H22: S.6 – 4. We are transparent. | I22: hoch | J22: Klare Disclosure-Regel. | K22: =Tabelle5225[[#This Row],[value_present]]*Tabelle5225[[#This Row],[binding_level]] -> 2
A23: 15 | B23: 86 | C23: VAL_04 | D23: 1 | E23: 1 | F23: Black-Box-Vermeidung als Designziel | G23: “prevent so called ‘Black Boxes’” | H23: S.8 – 6. We set the framework. | I23: Hoch | J23: Explainability-Anker vorhanden, aber nur auf Prinzipienniveau. | K23: =Tabelle5225[[#This Row],[value_present]]*Tabelle5225[[#This Row],[binding_level]] -> 1
A24: 15 | B24: 86 | C24: VAL_05 | D24: 1 | E24: 3 | F24: Fairness als Eigenschaft der AI-Lösungen genannt; Bias-Prävention durch Datenentfernung | G24: “transparent, auditable, fair, and fully documented.”; “we remove inappropriate data to avoid bias.” | H24: S.8 (fair); S.9 (avoid bias) | I24: Hoch | J24: Konkreter Anti-Bias-Kontrollschritt. | K24: =Tabelle5225[[#This Row],[value_present]]*Tabelle5225[[#This Row],[binding_level]] -> 3
A25: 15 | B25: 86 | C25: VAL_06 | D25: 1 | E25: 2 | F25: Keine Verarbeitung privacy-relevanter Daten ohne Rechtsgrundlage; Impact-Analysis-Paradigma: privacy & security by design | G25: “We never process privacy-relevant data without legal permission.”; “impact analysis is ‘privacy und security by design’.” | H25: S.7 (legal permission); S.8 (privacy by design) | I25: hoch | J25: Klare Privacy-Regel; stärkste Evidenz bleibt deontisch. | K25: =Tabelle5225[[#This Row],[value_present]]*Tabelle5225[[#This Row],[binding_level]] -> 2
A26: 15 | B26: 86 | C26: VAL_07 | D26: 1 | E26: 2 | F26: Security/Robustness als technische Anforderung an KI; Überblick über Datennutzung und Zugriffe als Security-Prinzip; Nutzung wird auf passende Use Cases begrenzt + Systeme gesichert | G26: “AI systems have to meet… technical requirements… such as security, robustness.”; “full overview of how customer related data is used and who has access”; “limit the usage to appropriate use cases and thoroughly secure our systems” | H26: S.4 (security/robustness); S.7 (access/secure) | I26: hoch | J26: Security-Regel mit konkreter Absicherungsrichtung. | K26: =Tabelle5225[[#This Row],[value_present]]*Tabelle5225[[#This Row],[binding_level]] -> 2
A27: 15 | B27: 86 | C27: VAL_08 | D27: 1 | E27: 3 | F27: Safety/Harm Prevention, deontisch „shall“.; Konkrete Kontrollregel (Stop-Kriterium). | G27: “In case of inconsistencies, we rather stop the AI system” | H27: S.8 (no harm); S.9 (stop on inconsistencies) | I27: Hoch | J27: Konkrete Harm-prevention-Stop-Regel. | K27: =Tabelle5225[[#This Row],[value_present]]*Tabelle5225[[#This Row],[binding_level]] -> 3
A28: 15 | B28: 86 | C28: VAL_09 | D28: 1 | E28: 2 | F28: Security/Robustness als technische Anforderung an KI; Konkrete Prüf-/Szenarioelemente. | G28: “AI systems have to meet… technical requirements… such as security, robustness.”; “full overview of how customer related data is used and who has access”; “limit the usage to appropriate use cases and thoroughly secure our systems”; “risks and chances scenarios or reliable disaster scenarios.” | H28: S.4 (robustness); S.8 (disaster scenarios) | I28: Hoch | J28: Robustheit explizit; kein Test-/Monitoringbeleg für 3. | K28: =Tabelle5225[[#This Row],[value_present]]*Tabelle5225[[#This Row],[binding_level]] -> 2
A29: 15 | B29: 86 | C29: VAL_10 | D29: 0 | I29: hoch | J29: Kein belastbarer Redress-/Complaint-Mechanismus. | K29: =Tabelle5225[[#This Row],[value_present]]*Tabelle5225[[#This Row],[binding_level]] -> 0
A30: 15 | B30: 86 | C30: VAL_11 | D30: 0 | I30: hoch | J30: Kein Inclusiveness-/Accessibility-Anker. | K30: =Tabelle5225[[#This Row],[value_present]]*Tabelle5225[[#This Row],[binding_level]] -> 0
A31: 15 | B31: 86 | C31: VAL_12 | D31: 0 | I31: hoch | J31: Kein Umwelt-/Green-AI-Anker im Short Doc. | K31: =Tabelle5225[[#This Row],[value_present]]*Tabelle5225[[#This Row],[binding_level]] -> 0
A32: 15 | B32: 86 | C32: VAL_13 | D32: 1 | E32: 1 | F32: Social benefit / well-being (kundenzentriert). | G32: “We enrich and simplify our customers’ lives.” | H32: S.5 – 3. We put our customers first. | I32: Hoch | J32: Konkreter Kundennutzen, aber ohne weitere Operationalisierung. | K32: =Tabelle5225[[#This Row],[value_present]]*Tabelle5225[[#This Row],[binding_level]] -> 1
A33: 15 | B33: 86 | C33: VAL_14 | D33: 1 | E33: 2 | F33: KI-Systeme müssen Regeln und Gesetzen untergeordnet sein; Keine Verarbeitung privacy-relevanter Daten ohne Rechtsgrundlage | G33: “We never process privacy-relevant data without legal permission.”; “AI systems have to meet… technical requirements… such as security, robustness.” | H33: S.4 (laws); S.7 (legal permission) | I33: hoch | J33: Deontische Compliance-Regel. | K33: =Tabelle5225[[#This Row],[value_present]]*Tabelle5225[[#This Row],[binding_level]] -> 2
A34: 15 | B34: 86 | C34: VAL_15 | D34: 0 | I34: hoch | J34: Nur Ethik-Rhetorik; keine explizite ethische Grenze/„do not“-Leitplanke. | K34: =Tabelle5225[[#This Row],[value_present]]*Tabelle5225[[#This Row],[binding_level]] -> 0
A35: 15 | B35: 86 | C35: VAL_16 | D35: 1 | E35: 3 | F35: Data quality/governance + fairness-bezogen.; Diverse/angemessene Dateninput-Verantwortung; Reset zur Entfernung falscher/biased Daten | G35: “we remove inappropriate data to avoid bias.”; “responsibility for a diverse and appropriate data input.”; “reset… in order to remove false or biased data.” | H35: S.9 – 7. We maintain control. | I35: mittel | J35: Konkreter Data-governance-/Data-quality-Kontrollschritt. | K35: =Tabelle5225[[#This Row],[value_present]]*Tabelle5225[[#This Row],[binding_level]] -> 3
A36: 15 | B36: 86 | C36: VAL_17 | D36: 0 | I36: hoch | J36: Kein KI-spezifischer IP-/Confidentiality-Anker. | K36: =Tabelle5225[[#This Row],[value_present]]*Tabelle5225[[#This Row],[binding_level]] -> 0
A37: 15 | B37: 86 | C37: VAL_18 | D37: 0 | I37: hoch | J37: Kein expliziter Human-rights-Frame im Sinne des Codebooks. | K37: =Tabelle5225[[#This Row],[value_present]]*Tabelle5225[[#This Row],[binding_level]] -> 0
K38: =Tabelle5225[[#This Row],[value_present]]*Tabelle5225[[#This Row],[binding_level]] -> 0
K39: =Tabelle5225[[#This Row],[value_present]]*Tabelle5225[[#This Row],[binding_level]] -> 0
K40: =Tabelle5225[[#This Row],[value_present]]*Tabelle5225[[#This Row],[binding_level]] -> 0
...

Sheet 00_DAX_Master
A1: company_id | B1: company_name_official | C1: brand_short | D1: sector_cluster | E1: industry_detail | F1: hq_country | G1: dax_member_as_of_date | H1: Marktkapitalisierung in Mio. € (Stand: 04.01.2026) | I1: notes_sampling
A2: 1 | B2: Adidas | C2: ADS | D2: Consumer | E2: Sportartikel | F2: Bayern | G2: 22. Juni 1998 | H2: 28070.86 | I2: Trotz intensiver Recherche auf offiziellen Konzernquellen und in Berichten gibt es keine öffentlich zugängliche KI‑Ethik‑ oder Responsible‑AI‑Policy von adidas
A3: 2 | B3: Airbus | C3: AIR | D3: Industrie | E3: Luftfahrt, Raumfahrt, Rüstung | F3: Niederlande | G3: 20. Sep. 2021 | H3: 146046.49 | I3: Keine öffentlichen, dedizierten „Responsible AI Policies“ im Sinne eines separaten Dokuments gefunden; die wichtigsten Aussagen sind in der Human‑rights‑Seite und im Digital‑Ethics‑Kapitel des Verhaltenskodex integriert.
A4: 3 | B4: Allianz | C4: ALV | D4: Finance | E4: Versicherungen | F4: Bayern | G4: 1. Juli 1988 | H4: 138065.08 | I4: Keine dedizierten öffentlichen „Allianz Standard for Responsible AI“‑Dokumente gefunden; der Standard wird nur intern erwähnt.
A5: 4 | B5: BASF | C5: BAS | D5: Materials/Chemicals | E5: Chemie | F5: Rheinland-Pfalz | G5: 1. Juli 1988 | H5: 36934 | I5: Es wurde keine öffentlich zugängliche, eigenständige „Data & AI Policy“ von BASF gefunden. Hinweise auf eine interne Data‑&‑AI‑Policy erscheinen im Responsible‑AI‑Text, sind aber nicht öffentlich abrufbar.
A6: 5 | B6: Bayer | C6: BAYN | D6: Materials/Chemicals | E6: Chemie, Pharma | F6: Nordrhein-Westfalen | G6: 1. Juli 1988 | H6: 33814.35 | I6: Mehrere relevante Dokumente gefunden.
A7: 6 | B7: Beiersdorf | C7: BEI | D7: Consumer | E7: Konsumgüter (Produktion) | F7: Hamburg | G7: 20. Juni 2022 | H7: 19043.54 | I7: Die einzige explizite AI‑Policy‑Aussage stammt aus dem Annual Report 2024. Die Code‑of‑Conduct‑Dokumente und die Human‑Rights‑Policy enthalten relevante Leitplanken zu digitaler Verantwortung, Daten‑ und Menschenrechtsschutz, aber keine spezifischen KI‑Prinzipien
A8: 7 | B8: BMW | C8: BMW | D8: Industrie | E8: Automobil (Produktion) | F8: Bayern | G8: 1. Juli 1988 | H8: 52864.52 | I8: Mehrere relevante Dokumente gefunden.
A9: 8 | B9: Brenntag | C9: BNR | D9: Materials/Chemicals | E9: Chemie (Handel) | F9: Nordrhein-Westfalen | G9: 20. Sep. 2021 | H9: 6654.82 | I9: Es konnten keine spezifischen öffentlichen KI‑Leitlinien oder Responsible‑AI‑Policies von Brenntag SE gefunden werden
A10: 9 | B10: Commerzbank | C10: CBK | D10: Finance | E10: Banken | F10: Hessen | G10: 27. Feb. 2023 | H10: 37853.56 | I10: Die zentrale AI-Quelle ist das Dokument „KI-Grundsätze im Commerzbank-Konzern“
A11: 10 | B11: Continental | C11: CON | D11: Industrie | E11: Automobil (Zulieferer) | F11: Niedersachsen | G11: 24. Sep. 2012 | H11: 12640.94 | I11: Mehrere semi-relevante Dokumente gefunden.
A12: 11 | B12: Daimler Truck | C12: DTG | D12: Industrie | E12: Nutzfahrzeuge (Produktion) | F12: Baden-Württemberg | G12: 21. März 2022 | H12: 25660.46 | I12: Keine eigenständigen, konzernweiten „Responsible AI Policy“ oder „AI Principles“ separat vom Code of Conduct/Integrity Code identifiziert
A13: 12 | B13: Deutsche Bank | C13: DBK | D13: Finance | E13: Banken | F13: Hessen | G13: 1. Juli 1988 | H13: 57682.6 | I13: Die konkretesten AI-Prinzipien lagen öffentlich am klarsten im Supplier Code of Conduct (AI & Data Ethics Principles) sowie Governance-Hinweise (z. B. „AI Oversight Forum“) in ESG/IR-Reports vor; darüber hinaus keine weiteren belastbaren Policy-Dokumente.
... A41: 40 | B41: Zalando | C41: ZAL | D41: Consumer | E41: Versandhandel (Mode) | F41: Berlin | G41: 20. Sep. 2021 | H41: 6113.98 | I41: relevante Inhalte zu KI-/Algorithmus-Werten und Governance sind über CDR-Report, Code of Ethics, ESG- und D&I-Dokumente sowie Tech-Blog-Artikel verteilt.

Sheet 01_Document_Log
A1: doc_id | B1: company_id | C1: doc_title | D1: doc_type | E1: publisher | F1: publication_date | G1: version | H1: language | I1: url | J1: access_date | K1: file_name_local | L1: inclusion_status | M1: exclusion_reason | N1: relevance_notes | O1: Inkludiert in Pilot?
A2: 1 | B2: 1 | C2: Fair Play Code of Conduct | D2: Code of Conduct | E2: adidas AG | F2: n.n. | G2: n.n. | H2: EN | I2: https://www.adidas-group.com/en/investors/corporate-governance/adidas-fair-play-code-of-conduct | J2: 16.02.2026 | K2: 001_01_FairPlayCode_1602026.pdf | L2: Nicht inkudiert | M2: Keine KI Relevanz | N2: Stellt umfassend die ethischen Erwartungen an alle adidas‑Mitarbeitenden dar (Antikorruption, Datenschutz, Verhalten), enthält Governance‑Mechanismen wie Schulungen und Berichtswege. Trotz fehlendem KI‑Bezug ist es das stärkste normative Dokument.
A3: 2 | B3: 1 | C3: Compliance Policy | D3: Code of Conduct | E3: adidas AG | F3: n.n. | G3: n.n. | H3: EN | I3: https://www.adidas-group.com/en/investors/corporate-governance/adidas-fair-play-code-of-conduct | J3: 16.02.2026 | K3: 002_01_compliance_policy_160226.pdf | L3: Nicht inkudiert | M3: Keine KI Relevanz | N3: Erläutert konkret die Regeln zu Bestechung, Geschenken, Betrug, Wettbewerbsrecht und Interessenkonflikten sowie die Pflichten und Verfahren bei Verstößen. Wichtiges Governance‑Rahmenwerk, obwohl keine KI‑Themen adressiert werden.
A4: 3 | B4: 1 | C4: Human Rights Policy | D4: Other | E4: adidas AG | F4: 01.02.2024 | G4: n.n. | H4: EN | I4: https://www.adidas-group.com/en/sustainability/transparency/policies | J4: 16.02.2026 | K4: 003_01_Human_Rights_Policy_160226.pdf | L4: Nicht inkudiert | M4: Keine KI Relevanz | N4: Verankert adidas’ Verpflichtung zu internationalen Menschenrechtsstandards und beschreibt Due‑Diligence‑Prozesse zur Identifizierung und Vermeidung negativer Auswirkungen. Relevante Werte wie Fairness, Gleichheit und Schutz vulnerabler Gruppen können später als Kontext für KI‑Ethik dienen.
A5: 4 | B5: 1 | C5: ETHICAL COMMUNICATION GUIDELINES | D5: Code of Conduct | E5: Adidas Foundation | F5: n.n. | G5: n.n. | H5: EN | I5: https://www.adidasfoundation.org/about/policies-and-guidelines | J5: 16.02.2026 | K5: 004_01_Ethical_comms_guide_160226.pdf | L5: Nicht inkudiert | M5: Keine KI Relevanz
A6: 5 | B6: 1 | C6: Safeguarding Policy | D6: Code of Conduct | E6: Adidas Foundation | F6: n.n. | G6: n.n. | H6: EN | I6: https://www.adidasfoundation.org/about/policies-and-guidelines | J6: 16.02.2026 | K6: 005_SafeguardingPolicy_160226.pdf | L6: Nicht inkudiert | M6: Keine KI Relevanz
A7: 6 | B7: 1 | C7: Supervisory Board Report 2024 | D7: Annual Report | E7: Adidas Group | F7: 01.03.2025 | G7: n.n. | H7: EN | I7: https://report.adidas-group.com/2024/en/to-our-shareholders/supervisory-board-report.html | J7: 16.02.2026 | K7: 006_01_Supervisory_Report_2024_160226.pdf | L7: Nicht inkudiert | M7: Keine KI Relevanz
A8: 7 | B8: 1 | C8: Integrated Management System Global Policy | D8: Sustainability Report | E8: Adidas AG | F8: 01.01.2026 | G8: n.n. | H8: EN | I8: https://www.adidas-group.com/de/nachhaltigkeit/transparenz/richtlinien?tag=Eigene+Standorte | J8: 16.02.2026 | K8: 007_01_IMSGP_160226.pdf | L8: Nicht inkudiert | M8: Keine KI Relevanz
B9: 1 | D9: AI Principles | E9: Adidas AG | L9: Nicht gefunden | N9: No public AI/Responsible AI guideline, policy or principles found (as of 2026‑02‑16)
B10: 1 | D10: AI Policy | E10: Adidas AG | L10: Nicht gefunden | N10: No public AI/Responsible AI guideline, policy or principles found (as of 2026‑02‑16)
B11: 1 | D11: Responsible AI / Ethics | E11: Adidas AG | L11: Nicht gefunden | N11: No public AI/Responsible AI guideline, policy or principles found (as of 2026‑02‑16)
A12: 8 | B12: 2 | C12: Our approach to Artificial Intelligence (AI) | D12: AI Policy | E12: Airbus SE | F12: n.n. | G12: n.n. | H12: EN | I12: https://www.airbus.com/en/sustainability-draft/our-approach-to-sustainability/human-rights | J12: 16.02.2026 | K12: 008_02_AI_Approach_160226 | L12: Inkludiert
A13: 9 | B13: 2 | C13: Airbus Code of Conduct – 2025 Edition | D13: Code of Conduct | E13: Airbus SE | F13: n.n. | G13: n.n. | H13: EN | I13: https://www.airbus.com/sites/g/files/jlcbta136/files/2025-04/2025-Airbus-Code-of-Conduct-EN.pdf | J13: 16.02.2026 | K13: 009_02_Code-of-Conduct_160226.pdf | L13: Inkludiert
A14: 10 | B14: 2 | C14: Airbus Supplier Code of Conduct | D14: Code of Conduct | E14: Airbus SE | F14: n.n. | G14: n.n. | H14: EN | I14: https://www.airbus.com/sites/g/files/jlcbta136/files/2021-07/Airbus-Supplier-Code-of-Conduct.pdf | J14: 16.02.2026 | K14: 010_02_Supplier-Code-of-Conduct_160226.pdf | L14: Nicht inkudiert | M14: Keine KI Relevanz
A15: 11 | B15: 2 | C15: Airbus Ethics & Compliance Anti‑Corruption Policy | D15: Other | E15: Airbus SE | F15: n.n. | G15: n.n. | H15: EN | I15: https://www.airbus.com/sites/g/files/jlcbta136/files/2021-10/Airbus-Ethics-and-Compliance-Anti-Corruption-Policy.pdf | J15: 16.02.2026 | K15: 011_02_Ethics-and-Compliance-Anti-Corruption-Policy_160226.pdf | L15: Nicht inkudiert | M15: Keine KI Relevanz
A16: 12 | B16: 2 | C16: Pioneering sustainable aerospace (Sustainability publication 2025) | D16: Sustainability Report | E16: Airbus SE | F16: 2025 | G16: n.n. | H16: EN | I16: https://www.airbus.com/sites/g/files/jlcbta136/files/2025-04/2025_Airbus_Pioneering_sustainable_aerospace_publication.pdf | J16: 16.02.2026 | K16: 012_02_Pioneering_sustainable_aerospace_publication_160226.pdf | L16: Nicht inkudiert | M16: Keine KI Relevanz
A17: 13 | B17: 2 | C17: Airbus Summit 2025 – Harnessing the power of responsible AI | D17: Press Release | E17: Airbus SE | F17: 25.03.2025 | G17: n.n. | H17: EN | I17: https://www.airbus.com/en/airbus-summit-2025/harnessing-the-power-of-responsible-ai | J17: 16.02.2026 | K17: 013_02_Harnessing the power of responsible AI _160226pdf | L17: Nicht inkudiert | M17: PR ohne normative Substanz
A18: 14 | B18: 2 | C18: Information Notice of the 2025 Annual General Meeting | D18: Annual Report | E18: Airbus SE | F18: 15.04.2025 | G18: n.n. | I18: https://www.airbus.com/sites/g/files/jlcbta136/files/2025-03/information_notice.pdf | J18: 16.02.2026 | K18: 014_02_Annual_General_Meeting_2025_160226.pdf | L18: Nicht inkudiert | M18: Keine KI Relevanz
A19: 15 | B19: 2 | C19: Artificial Intelligence | D19: Website Page | E19: Airbus SE | F19: n.n. | G19: n.n. | H19: EN | I19: https://www.airbus.com/en/innovation/digital-transformation/artificial-intelligence | J19: 16.02.2026 | K19: 015_02_AI_Website_160226 | L19: Nicht inkudiert | M19: PR ohne normative Substanz | N19: Kein Bezug zur KI Ethikrichtlinien; beschreibt nur technischen/ wirtschaftlichen Einsatz von KI
B20: 2 | D20: AI Principles | E20: Airbus SE | L20: Nicht gefunden | N20: No public AI/Responsible AI guideline or principles found (as of 2026‑02‑16)
B21: 2 | D21: Responsible AI / Ethics | E21: Airbus SE | L21: Nicht gefunden | N21: No public AI/Responsible AI guideline or principles found (as of 2026‑02‑16)
A22: 16 | B22: 3 | C22: Responsible Use of Artificial Intelligence (AI) | D22: Responsible AI / Ethics | E22: Allianz SE | F22: n.n. | G22: n.n. | H22: EN | I22: https://www.allianz.com/en/about-us/strategy-values/responsible-use-of-artificial-intelligence.html | J22: 16.02.2026 | K22: 016_03_Responsible Use of Artificial Intelligence_160226.pdf | L22: Inkludiert | O22: X
A23: 17 | B23: 3 | C23: Allianz Code of Conduct | D23: Code of Conduct | E23: Allianz SE | F23: 2025 | G23: n.n. | H23: EN | I23: https://www.allianz.com/content/dam/onemarketing/azcom/Allianz_com/about-us/strategy-values/compliance/code-of-conduct/code-of-conduct-accessible.pdf | J23: 16.02.2026 | K23: 017_03_code-of-conduct_160226.pdf | L23: Inkludiert | O23: X
A24: 18 | B24: 3 | C24: Privacy Statement – Data Ethics section | D24: Other | E24: Allianz SE | F24: 2025 | G24: n.n. | H24: EN | I24: https://www.allianz.com/en/privacy-statement.html | J24: 16.02.2026 | K24: 018_03_Privacy Statement_160226.pdf | L24: Inkludiert
A25: 19 | B25: 3 | C25: Allianz Privacy Standard – Public Version | D25: Other | E25: Allianz SE | F25: 43221 | G25: 1.0 | H25: EN | I25: https://www.allianzgloballife.com/content/dam/onemarketing/azgl/allianzgloballife/doc/31122019/en_gb/Allianz-Privacy-Standard_PUBLIC_EN.pdf | J25: 16.02.2026 | K25: 019_03_Privacy-Standard_PUBLIC_EN_160226.pdf | L25: Nicht inkudiert | M25: Duplikat / Veraltete Version
A26: 20 | B26: 3 | C26: Allianz Group Sustainability Report 2023 – Data ethics/AI governance sections | D26: Sustainability Report | E26: Allianz SE | F26: 2023 | G26: n.n. | H26: EN | I26: https://www.allianz.com/content/dam/onemarketing/azcom/Allianz_com/sustainability/documents/Allianz_Group_Sustainability_Report_2023-web.pdf | J26: 16.02.2026 | K26: 020_03_Sustainability_Report_2023_160226.pdf | L26: Nicht inkudiert | M26: Duplikat / Veraltete Version
A27: 21 | B27: 3 | C27: Responsible AI: a sustainable approach to transformative technology | D27: Responsible AI / Ethics | E27: Allianz Global Investors (subsidiary) | F27: n.n. | G27: n.n. | H27: EN | I27: https://www.allianzgi.com/documents/Responsible-AI-a-sustainable-approach-to-transformative-technology | J27: 16.02.2026 | K27: 021_03_Responsible_AI_160226.pdf | L27: Inkludiert | N27: Tochtergesellschaft der Allianz SE
B28: 3 | D28: AI Principles | E28: Allianz SE | L28: Nicht gefunden | N28: No public AI policy or principles found (as of 2026‑02‑16)
B29: 3 | D29: AI Policy | E29: Allianz SE | L29: Nicht gefunden | N29: No public AI policy or principles found (as of 2026‑02‑16)
A30: 22 | B30: 4 | C30: Responsible AI at BASF | D30: Responsible AI / Ethics | E30: BASF SE | F30: n.n. | G30: n.n. | H30: EN | I30: https://www.basf.com/global/en/who-we-are/digitalization/artificial-intelligence/Responsible-AI-at-BASF | J30: 16.02.2026 | K30: 022_04_Responsible_AI_160226.pdf | L30: Inkludiert | O30: X
A31: 23 | B31: 4 | C31: BASF Code of Conduct | D31: Code of Conduct | E31: BASF SE | F31: n.n. | G31: n.n. | H31: EN | I31: https://www.basf.com/dam/jcr:0304db1d-bcbb-3015-a965-62627c1b61d2/basf/www/global/documents/en/investor-relations/calendar-and-publications/reports/2025/BASF_Code-of-Conduct.pdf | J31: 16.02.2026 | K31: 023_04_Code-of-Conduct_160226.pdf | L31: Inkludiert | O31: X
A32: 24 | B32: 4 | C32: Data protection @ BASF – Data processing in the BASF Group | D32: Other | E32: BASF SE | F32: n.n. | G32: n.n. | H32: EN | I32: https://www.basf.com/global/en/legal/data-protection-at-basf | J32: 16.02.2026 | K32: 024_04_Data protection_160226.pdf | L32: Inkludiert
A33: 25 | B33: 4 | C33: BASF Group’s Policy Statement on Human Rights | D33: Other | E33: BASF SE | F33: n.n. | G33: n.n. | H33: EN | I33: https://www.basf.com/dam/jcr:4944a24f-defc-4987-9dd6-d38dba24efd9/basf/www/global/documents/en/sustainability/we-value-people-and-treat-them-with-respect/human-rights/Human-Rights-Policy-Statement-BASF-Group.pdf | J33: 16.02.2026 | K33: 025_04_Human-Rights-Policy-Statement_160226.pdf | L33: Nicht inkudiert | M33: Keine KI Relevanz
A34: 26 | B34: 4 | C34: Supplier Code of Conduct (Version 2024) | D34: Code of Conduct | E34: BASF SE | F34: 45474 | G34: n.n. | H34: EN | I34: https://www.basf.com/dam/jcr:83c0af8a-4e46-37c0-945f-3fd15ff4fca3/basf/www/global/documents/en/about-us/suppliers-and-partners/supplier-code-of-conduct/Supplier_Code_of_conduct_Version%202024%20-%20English.pdf | J34: 16.02.2026 | K34: 025_04_Supplier_Code_of_conduct_160226.pdf | L34: Nicht inkudiert | M34: Keine KI Relevanz
B35: 4 | D35: AI Principles | E35: BASF SE | L35: Nicht gefunden | N35: No public AI policy or principles found (as of 2026‑02‑16)
B36: 4 | D36: AI Policy | E36: BASF SE | L36: Nicht gefunden | N36: No public AI policy or principles found (as of 2026‑02‑16)
A37: 27 | B37: 5 | C37: Bioethical Principles – AI in the context of human healthcare | D37: AI Principles | E37: Bayer AG | F37: n.n. | G37: n.n. | H37: EN | I37: https://www.bayer.com/en/sustainability/bioethical-principles | J37: 16.02.2026 | K37: 027_05_Bioethical Principles_160226.pdf | L37: Inkludiert | O37: X
A38: 28 | B38: 5 | C38: Generative Artificial Intelligence (GenAI) Guidance and Rules – version 3 | D38: AI Policy | E38: Bayer AG | F38: 17.10.2024 | G38: V3 | H38: EN | I38: https://idnet.bayer.com/sites/idnet/files/final-en-genai-guidelines-and-rules-v3.pdf | J38: 16.02.2026 | K38: 028_05_genai-guidelines_160226.pdf | L38: Inkludiert | O38: X
A39: 29 | B39: 5 | C39: Our Code of Conduct – Responsible use of Artificial Intelligence section | D39: Code of Conduct | E39: Bayer AG | F39: n.n. | G39: n.n. | H39: EN | I39: https://www.bayer.com/en/commitments/code-of-conduct | J39: 16.02.2026 | K39: 029_05_Code of Conduct_160226.pdf | L39: Inkludiert | O39: X
A40: 30 | B40: 5 | C40: Unleashing the Potential of AI – AI Ethics and Responsibility section | D40: Responsible AI / Ethics | E40: Bayer AG | F40: n.n. | G40: n.n. | H40: EN | I40: https://www.bayer.com/en/innovation/unleashing-the-potential-of-ai | J40: 16.02.2026 | K40: 030_05_Unleashing the Potential of AI_160226.pdf | L40: Inkludiert
...

Sheet 02_Values_Codebook
A1: value_id | B1: value_name | C1: definition_short | D1: include_rules | E1: exclude_rules | F1: synonyms_terms | G1: example_phrases | H1: notes_boundary_cases
A2: VAL_01 | B2: Human Agency & Oversight | C2: Menschen behalten Kontrolle/Überwachung über KI | D2: Wenn menschliche Kontrolle/Override/Review explizit gefordert | E2: Reine Floskel „human-centered“ ohne Mechanik | F2: human oversight; human-in-the-loop; human control; override; review | G2: human review; override; escalation to humans | H2: Unterscheide Wert vs Governance-Kriterium 'Eskalationswege'
A3: VAL_02 | B3: Accountability & Responsibility | C3: Zuständigkeit/Verantwortung für KI-Entscheidungen/Outcomes | D3: Wenn Verantwortliche Rollen/Verantwortungsprinzip genannt | E3: Reines „we take responsibility“ ohne Bezug zu KI | F3: responsibility; accountability; ownership; governance | G3: clear accountability; responsible for AI | H3: Kann mit GOV_01 (Zuständigkeiten) kollidieren – hier nur als Wert codieren
A4: VAL_03 | B4: Transparency | C4: Nachvollziehbarkeit über Einsatz/Zweck/Entscheidungslogik | D4: Wenn Transparenzpflichten oder Offenlegung zu KI erwähnt | E4: Transparenz nur im Sinne von „Kommunikation“ ohne KI-Bezug | F4: transparency; disclosure; openness | G4: transparent use of AI; disclose AI involvement | H4: VAL_03 codieren, wenn Offenlegung, Identifizierbarkeit oder der Einsatz von KI gemeint ist (z. B. disclose AI involvement, AI system identifiable). Nicht als VAL_04 codieren, solange keine Erklärung/Interpretierbarkeit von Output, Modell oder Entscheidungslogik gefordert wird.
A5: VAL_04 | B5: Explainability | C5: Erklärbarkeit von KI-Entscheidungen/Outputs | D5: Wenn Erklärbarkeit, Interpretierbarkeit oder Verständlichkeit von KI-Output oder Entscheidungslogik gefordert wird; dazu zählen auch Formulierungen wie "comprehensible decision-making processes" oder die Vermeidung von "black boxes", sofern sie auf Verstehbarkeit/Erklärung und nicht nur auf Offenlegung zielen. | E5: „transparent“ ohne Erklärkomponente | F5: explainability; interpretability; explanation | G5: provide explanations; explain model outputs | H5: Technisch vs kommunikativ – beide zählen
A6: VAL_05 | B6: Fairness & Non-Discrimination | C6: Vermeidung unfairer Benachteiligung/Bias | D6: Wenn Bias/Benachteiligung/Anti-Diskriminierung bei KI genannt | E6: Allgemeine Diversity-Statements ohne KI-Bezug | F6: fairness; bias mitigation; non-discrimination; equity | G6: avoid bias; non-discriminatory outcomes | H6: Achtung: Legal Compliance ist VAL_14, nicht hier
A7: VAL_06 | B7: Privacy & Data Protection | C7: Schutz personenbezogener Daten/Datensparsamkeit | D7: Wenn Datenschutz bei KI/Training/Use erwähnt | E7: Datenschutz rein allgemein ohne KI-Kontext | F7: privacy; data protection; GDPR; data minimization | G7: privacy by design; data minimization | H7: Kann auch als Governance (Tools/Checks) auftauchen – hier Wert
A8: VAL_07 | B8: Security & Cybersecurity | C8: Schutz vor Angriffen/Manipulation/Leakage | D8: Wenn Security für KI-Systeme oder Daten betont | E8: Allgemeine IT-Security ohne KI-Kontext (Grenzfall) | F8: security; cybersecurity; adversarial; secure-by-design | G8: protect against attacks; secure systems | H8: Grenzfall: Wenn nur IT allgemein -> evtl. nicht codieren
A9: VAL_08 | B9: Safety & Harm Prevention | C9: Vermeidung von Schäden (physisch, psychisch, sozial) | D9: Wenn Risiko/Schadensvermeidung durch KI erwähnt | E9: Nur „safe“ als Marketingwort | F9: safety; harm prevention; risk reduction | G9: avoid harm; safe AI | H9: VAL_08 zusätzlich zu VAL_09 codieren, wenn Schäden, unbeabsichtigte Folgen, Missbrauch oder Safety explizit benannt sind. Reine Robustheits-/Zuverlässigkeitsrhetorik ohne Harm-/Safety-Anker bleibt nur VAL_09.
A10: VAL_09 | B10: Technical Robustness & Reliability | C10: Zuverlässigkeit, Stabilität, Fehlerresistenz | D10: Wenn Robustheit, Zuverlässigkeit, Genauigkeit, Testing oder Monitoring ausdrücklich auf das Erreichen intendierter Ergebnisse, Fehlerresistenz oder stabile Funktion von KI zielen. Bloßes Monitoring/Feedback ohne Bezug zu Output-Qualität oder intended outcome reicht nicht. | E10: Reine Qualitätsfloskel ohne Bezug | F10: robustness; reliability; resilience; testing | G10: robust and reliable; tested systems | H10: Kann in GOV_03 (Tools/Checks) konkret werden
A11: VAL_10 | B11: Contestability & Redress | C11: Anfechtbarkeit, Beschwerde, Wiedergutmachung | D11: Wenn Betroffene Einspruch/Review/Redress bei KI-Entscheidungen haben | E11: Reine Customer-Service Aussagen ohne KI | F11: appeal; contest; redress; complaint | G11: right to contest; grievance mechanism | H11: Stark verwandt mit GOV_06 (Eskalation) – hier Wert
A12: VAL_11 | B12: Inclusiveness & Accessibility | C12: Einbezug/Barrierefreiheit/Teilhabe | D12: Wenn KI inklusiv/zugänglich gestaltet werden soll | E12: Allgemeine DEI-/HR-Aussagen ohne KI-Bezug ausschließen. Ebenfalls ausschließen: "inclusion in data sets", repräsentative Daten oder Bias-Minderung ohne Bezug zu Accessibility, Teilhabe oder inklusivem Design; diese Fälle primär unter VAL_05 und/oder VAL_16 prüfen. | F12: accessibility; inclusiveness; participation | G12: inclusive design; accessible AI | H12: Wenn nur HR-DEI -> eher raus
... A19: VAL_18 | B19: Human Rights | C19: Menschenrechte als Rahmen (UNGP etc.) | D19: Wenn Menschenrechte, dignity, UDHR/UNGP oder einzelne Rechte ausdrücklich als Menschenrechtsrahmen für KI genannt werden; Privacy zählt zusätzlich als VAL_18 nur dann, wenn sie explizit als human right oder im Human-Rights-Framework verankert wird. | E19: Allgemeine Werte ohne Human-Rights-Bezug | F19: human rights; dignity; UNGP | G19: respect human rights; protect dignity | H19: Nicht jedes Doc wird das haben – ok

Sheet 03c_Values_Coding_PILOT
A1: company_id | B1: doc_id | C1: value_id | D1: value_present | E1: binding_level | F1: binding_justification | G1: evidence_quote | H1: evidence_location | I1: coder_confidence | J1: notes | K1: value_points
A2: 3 | B2: 16 | C2: VAL_01 | D2: 1 | E2: 2 | F2: KI-Nutzung muss Kundenautonomie respektieren, Risikobasierte menschliche Kontrolle wird zugesichert | G2: “Each usage of AI systems must respect customers’ autonomy and decision-making.”; “We ensure an appropriate, risk-based level of human control.” | H2: S. 5, 8 | I2: Hoch | J2: Deontisch („must respect…“) + human control. | K2: =Tabelle52[[#This Row],[value_present]]*Tabelle52[[#This Row],[binding_level]] -> 2
A3: 3 | B3: 16 | C3: VAL_02 | D3: 1 | E3: 1 | F3: AI-Systeme werden in Produktion überwacht, inkl. Feedback | G3: “We monitor AI systems in production… integrating user feedback.” | H3: S. 3 | I3: Hoch | J3: Monitoring/Feedback als Accountability-Indiz. | K3: =Tabelle52[[#This Row],[value_present]]*Tabelle52[[#This Row],[binding_level]] -> 1
A4: 3 | B4: 16 | C4: VAL_03 | D4: 1 | E4: 1 | F4: Kunden werden bei direkter KI-Interaktion informiert | G4: “We inform customers whenever they interact directly with an AI system, such as a chatbot.” | H4: S. 3 | I4: Hoch | J4: Kunden-Disclosure bei KI-Interaktion | K4: =Tabelle52[[#This Row],[value_present]]*Tabelle52[[#This Row],[binding_level]] -> 1
A5: 3 | B5: 16 | C5: VAL_04 | D5: 1 | E5: 1 | F5: Interpretierbarkeit wird risikobasiert angestrebt | G5: “We follow a risk-based approach to attain suitable levels of interpretability.” | H5: S. 3 | I5: Hoch | J5: Interpretability explizit (risk-based). | K5: =Tabelle52[[#This Row],[value_present]]*Tabelle52[[#This Row],[binding_level]] -> 1
A6: 3 | B6: 16 | C6: VAL_05 | D6: 1 | E6: 1 | F6: Vermeidung direkter/indirekter Diskriminierung; Bias wird in Daten und Modellen adressiert | G6: “We commit to avoiding… discrimination… in line with applicable non-discrimination law.”; “We mitigate potential bias both in the data itself… as well as… in each individual model.” | H6: S. 4, 5 | I6: Hoch | J6: Anti-Discrimination + Bias-Mitigation. | K6: =Tabelle52[[#This Row],[value_present]]*Tabelle52[[#This Row],[binding_level]] -> 1
A7: 3 | B7: 16 | C7: VAL_06 | D7: 1 | E7: 3 | F7: KI-Nutzung nur im Rahmen von Privacy Laws/Standards;Privacy Risk Assessment als Pflicht-Check bei Personal Data | G7: “AI systems may only be used… including the Allianz Privacy Standard.”; “perform a dedicated privacy risk assessment whenever personal data are utilised in an AI system.” | H7: S. 4, 6 | I7: Mittel | J7: Privacy + konkreter Pflicht-Check (Risk Assessment). | K7: =Tabelle52[[#This Row],[value_present]]*Tabelle52[[#This Row],[binding_level]] -> 3
A8: 3 | B8: 16 | C8: VAL_07 | D8: 1 | E8: 1 | F8: Cybersecurity & Resilience über den KI-Lifecycle | G8: “We ensure… cybersecurity and resilience measures… throughout the life-cycle of an AI System.” | H8: S. 4 | I8: Hoch | K8: =Tabelle52[[#This Row],[value_present]]*Tabelle52[[#This Row],[binding_level]] -> 1
A9: 3 | B9: 16 | C9: VAL_08 | D9: 0 | I9: Hoch | J9: Nicht nachweisbar. | K9: =Tabelle52[[#This Row],[value_present]]*Tabelle52[[#This Row],[binding_level]] -> 0
A10: 3 | B10: 16 | C10: VAL_09 | D10: 1 | E10: 1 | F10: Monitoring zur Sicherstellung beabsichtigter Outcomes (Reliability) | G10: “We monitor AI systems in production… [to] match the intended outcome…” | H10: S. 3 | I10: Mittel | J10: Reliability/Accuracy über Monitoring, ohne Test-/Robustness-Details. | K10: =Tabelle52[[#This Row],[value_present]]*Tabelle52[[#This Row],[binding_level]] -> 1
A11: 3 | B11: 16 | C11: VAL_10 | D11: 0 | I11: Hoch | J11: Nicht nachweisbar. | K11: =Tabelle52[[#This Row],[value_present]]*Tabelle52[[#This Row],[binding_level]] -> 0
A12: 3 | B12: 16 | C12: VAL_11 | D12: 0 | I12: Hoch | J12: Nicht nachweisbar. | K12: =Tabelle52[[#This Row],[value_present]]*Tabelle52[[#This Row],[binding_level]] -> 0
A13: 3 | B13: 16 | C13: VAL_12 | D13: 0 | I13: Hoch | J13: Nicht nachweisbar. | K13: =Tabelle52[[#This Row],[value_present]]*Tabelle52[[#This Row],[binding_level]] -> 0
A14: 3 | B14: 16 | C14: VAL_13 | D14: 0 | I14: Hoch | J14: Nicht nachweisbar. | K14: =Tabelle52[[#This Row],[value_present]]*Tabelle52[[#This Row],[binding_level]] -> 0
A15: 3 | B15: 16 | C15: VAL_14 | D15: 1 | E15: 2 | F15: AI-Use Cases an Gesetze/Standards gebunden; Illegale KI-Systeme werden nicht entwickelt/genutzt | G15: “AI systems and use cases may only be used in line with applicable laws and Allianz standards.”; “We do not develop or use AI Systems, which are in violation of the law.” | H15: S. 1,3 | I15: Hoch | J15: „may only“ + Verbot illegaler KI. | K15: =Tabelle52[[#This Row],[value_present]]*Tabelle52[[#This Row],[binding_level]] -> 2
A16: 3 | B16: 16 | C16: VAL_15 | D16: 0 | I16: Mittel | J16: „Prohibited AI“ wird hier nur als Gesetzesverstoß formuliert (keine expliziten ethischen Leitplanken jenseits Compliance). | K16: =Tabelle52[[#This Row],[value_present]]*Tabelle52[[#This Row],[binding_level]] -> 0
A17: 3 | B17: 16 | C17: VAL_16 | D17: 1 | E17: 2 | F17: Datenqualität wird als Voraussetzung für Training/Use gefordert | G17: “data quality has to be ensured when training and using AI Systems… through… data governance.” | H17: S. 5 | I17: Hoch | J17: Data Quality/Governance explizit für KI. | K17: =Tabelle52[[#This Row],[value_present]]*Tabelle52[[#This Row],[binding_level]] -> 2
A18: 3 | B18: 16 | C18: VAL_17 | D18: 0 | I18: Hoch | J18: Nicht nachweisbar. | K18: =Tabelle52[[#This Row],[value_present]]*Tabelle52[[#This Row],[binding_level]] -> 0
A19: 3 | B19: 16 | C19: VAL_18 | D19: 0 | I19: Hoch | J19: Nicht nachweisbar. | K19: =Tabelle52[[#This Row],[value_present]]*Tabelle52[[#This Row],[binding_level]] -> 0
A20: 4 | B20: 22 | C20: VAL_01 | D20: 1 | E20: 1 | F20: Human oversight + Accountability-Mechanismen;Keine autonomen KI-Entscheidungen mit materiellem Impact auf Mitarbeitende | G20: “...subject to human oversight and accountability mechanisms.”; “AI is not used to make autonomous decisions that have a material impact on employees.” | H20: S.2 – Prinzip 3 „Accountable“ | I20: hoch | J20: Human oversight + Verbot autonomer Entscheidungen mit materiellem Impact (Employees). | K20: =Tabelle52[[#This Row],[value_present]]*Tabelle52[[#This Row],[binding_level]] -> 1
A21: 4 | B21: 22 | C21: VAL_02 | D21: 1 | E21: 1 | F21: Verantwortung für Impact der KI-Anwendungen | G21: “We take responsibility for the impact of our AI applications…” | H21: S.2 – Prinzip 3 „Accountable“ | I21: hoch | J21: Verantwortung für Impact explizit. | K21: =Tabelle52[[#This Row],[value_present]]*Tabelle52[[#This Row],[binding_level]] -> 1
A22: 4 | B22: 22 | C22: VAL_03 | D22: 1 | E22: 1 | F22: Transparenz + nachvollziehbare Entscheidungsprozesse | G22: “We ensure that our AI applications are transparent…” | H22: S.2 – Prinzip 2 „Transparent“ | I22: hoch | J22: „transparent“ für AI applications. | K22: =Tabelle52[[#This Row],[value_present]]*Tabelle52[[#This Row],[binding_level]] -> 1
A23: 4 | B23: 22 | C23: VAL_04 | D23: 1 | E23: 1 | F23: Entscheidungsprozesse sollen für Stakeholder „comprehensible“ sein | G23: “...decision-making processes that are comprehensible to stakeholders.” | H23: S.2 – Prinzip 2 „Transparent“ | I23: mittel | J23: „comprehensible decision-making processes“ → interpretierbar/erklärnah (Grenzfall zu VAL_03). | K23: =Tabelle52[[#This Row],[value_present]]*Tabelle52[[#This Row],[binding_level]] -> 1
A24: 4 | B24: 22 | C24: VAL_05 | D24: 1 | E24: 1 | F24: Fairness, Equal opportunity, Anti-Discrimination | G24: “...reject discrimination.” | H24: S.2 – Prinzip 4 „Fair and Unbiased“ | I24: hoch | J24: Anti-Discrimination klar. | K24: =Tabelle52[[#This Row],[value_present]]*Tabelle52[[#This Row],[binding_level]] -> 1
A25: 4 | B25: 22 | C25: VAL_06 | D25: 1 | E25: 1 | F25: Privacy als „essential human right“ über gesamten Lifecycle | G25: “...protect the essential human right of an individual’s privacy throughout the entire life cycle…” | H25: S.2 – Prinzip 6 „Privacy Preserving“ | I25: hoch | J25: Privacy über gesamten Lifecycle. | K25: =Tabelle52[[#This Row],[value_present]]*Tabelle52[[#This Row],[binding_level]] -> 1
A26: 4 | B26: 22 | C26: VAL_07 | D26: 1 | E26: 1 | F26: Security: Integrität/Vertraulichkeit/Verfügbarkeit/Authentizität | G26: “...maintaining the integrity, confidentiality, availability and authenticity…” | H26: S.2 – Prinzip 5 „Secure“ | I26: hoch | J26: Schutzziele inkl. confidentiality/authenticity. | K26: =Tabelle52[[#This Row],[value_present]]*Tabelle52[[#This Row],[binding_level]] -> 1
A27: 4 | B27: 22 | C27: VAL_08 | D27: 1 | E27: 1 | F27: Wohlbefinden & Sicherheit von Individuen/Communities priorisiert; Robust & Safe: reliability, accuracy, safety | G27: “...prioritizing the well-being and safety of individuals and communities.”; “...focus on reliability, accuracy, and safety.” | H27: S.2 – Prinzip 1 & 7 | I27: mittel | J27: „safety“ (well-being/safety; robust & safe) vorhanden, aber ohne konkrete Harm-Controls. | K27: =Tabelle52[[#This Row],[value_present]]*Tabelle52[[#This Row],[binding_level]] -> 1
A28: 4 | B28: 22 | C28: VAL_09 | D28: 1 | E28: 1 | F28: Robust & Safe: reliability, accuracy, safety | G28: “...focus on reliability, accuracy, and safety.” | H28: S.2 – Prinzip 7 „Robust & Safe“ | I28: hoch | J28: reliability/accuracy explizit. | K28: =Tabelle52[[#This Row],[value_present]]*Tabelle52[[#This Row],[binding_level]] -> 1
A29: 4 | B29: 22 | C29: VAL_10 | D29: 0 | I29: hoch | J29: Nicht nachweisbar. | K29: =Tabelle52[[#This Row],[value_present]]*Tabelle52[[#This Row],[binding_level]] -> 0
A30: 4 | B30: 22 | C30: VAL_11 | D30: 0 | I30: hoch | J30: Nicht nachweisbar. | K30: =Tabelle52[[#This Row],[value_present]]*Tabelle52[[#This Row],[binding_level]] -> 0
A31: 4 | B31: 22 | C31: VAL_12 | D31: 0 | I31: hoch | J31: Nicht nachweisbar. | K31: =Tabelle52[[#This Row],[value_present]]*Tabelle52[[#This Row],[binding_level]] -> 0
A32: 4 | B32: 22 | C32: VAL_13 | D32: 0 | I32: hoch | J32: „create value“ zu allgemein; keine wert-/KI-spezifische Evidenz. | K32: =Tabelle52[[#This Row],[value_present]]*Tabelle52[[#This Row],[binding_level]] -> 0
A33: 4 | B33: 22 | C33: VAL_14 | D33: 1 | E33: 2 | F33: Responsible AI an EU AI Act/GDPR und Werte gebunden; KI für „Prohibited Practices“ wird strikt verboten (Policy-Verweis); Zentrales Inventar + Assessments zur Compliance/Risikosteuerung | G33: “...following laws like the EU AI Act and GDPR...”; “...strictly prohibiting AI in applications related to ‘Prohibited Practices’...”; “BASF maintains a central inventory and conducts necessary assessments to ensure compliance…” | H33: S.1 – Intro & „Commitment…“ | I33: mittel | J33: Laws (EU AI Act/GDPR) + „strictly prohibiting“; Inventory/Assessments als mögliche Prozess-Operationalisierung (Grenzfall BIND 2 vs 3). | K33: =Tabelle52[[#This Row],[value_present]]*Tabelle52[[#This Row],[binding_level]] -> 2
A34: 4 | B34: 22 | C34: VAL_15 | D34: 1 | E34: 1 | F34: Responsible AI als ethisch & accountable definiert; KI-Nutzung an Code of Conduct & Human Rights Policy gekoppelt | G34: “Responsible AI means developing, deploying, and using AI systems ethically and accountably.”; “...in accordance with our company’s values and ethical standards as described in our Code of Conduct…” | H34: S.1 – Definition;S.2 – Prinzip 1 | I34: hoch | J34: „ethically“ + Werte/CoC-Verweis. | K34: =Tabelle52[[#This Row],[value_present]]*Tabelle52[[#This Row],[binding_level]] -> 1
A35: 4 | B35: 22 | C35: VAL_16 | D35: 1 | E35: 1 | F35: Fokus auf Data & AI Governance (Daten als Schlüsselressource) | G35: “Our data is crucial for AI solutions, so we focus on strong data and AI governance.” | H35: S.1 – Intro | I35: mittel | J35: „data and AI governance“ genannt, aber ohne konkrete Data-Quality-Mechanik. | K35: =Tabelle52[[#This Row],[value_present]]*Tabelle52[[#This Row],[binding_level]] -> 1
A36: 4 | B36: 22 | C36: VAL_17 | D36: 0 | I36: mittel | J36: „confidentiality“ erscheint im Security-Kontext (VAL_07); kein IP/Trade-secret/IPR-Bezug. | K36: =Tabelle52[[#This Row],[value_present]]*Tabelle52[[#This Row],[binding_level]] -> 0
A37: 4 | B37: 22 | C37: VAL_18 | D37: 1 | E37: 1 | F37: Human Rights Management Policy als Bezugspunkt; Privacy als „essential human right“ über gesamten Lifecycle | G37: “...protect the essential human right of an individual’s privacy throughout the entire life cycle…”; “...set forth in BASF’s Human Rights Management Policy…” | H37: S.2 – Prinzip 1 & 6 | I37: mittel | J37: Human Rights Policy + „essential human right“ (privacy) explizit. | K37: =Tabelle52[[#This Row],[value_present]]*Tabelle52[[#This Row],[binding_level]] -> 1
A38: 5 | B38: 27 | C38: VAL_01 | D38: 1 | E38: 1 | F38: Autonomie wird respektiert; Harm Prevention/Wellbeing als Ziel; Schutz menschlicher Autonomie in entwickelten/verkauften/genutzten AI-Lösungen | G38: “We respect personal autonomy, strive to promote individual and collective wellbeing and preventing harm.”; “We will protect human autonomy in AI solutions that we develop, sell or use. | H38: S.8 – AI (Guiding Principles) | I38: hoch | J38: Autonomie explizit („respect/protect human autonomy“). | K38: =Tabelle52[[#This Row],[value_present]]*Tabelle52[[#This Row],[binding_level]] -> 1
A39: 5 | B39: 27 | C39: VAL_02 | D39: 1 | E39: 1 | F39: Inklusion (Datensätze), Fairness und Accountability werden angestrebt | G39: “...striving for inclusion in our data sets, fairness and accountability.” | H39: S.8 – AI (Guiding Principles) | I39: mittel | J39: „accountability“ genannt (ohne Rollen/Mechanik). | K39: =Tabelle52[[#This Row],[value_present]]*Tabelle52[[#This Row],[binding_level]] -> 1
A40: 5 | B40: 27 | C40: VAL_03 | D40: 1 | E40: 1 | F40: KI soll transparent genutzt werden (Commitment) | G40: “At Bayer, we commit to use AI transparently and responsibly.” | H40: S.8 – AI (Guiding Principles) | I40: hoch | J40: „commit to use AI transparently“. | K40: =Tabelle52[[#This Row],[value_present]]*Tabelle52[[#This Row],[binding_level]] -> 1
...

Sheet 05b_Governance_Coding_PILOT
A1: company_id | B1: doc_id | C1: gov_crit_id | D1: doc_id_primary_evidence | E1: score_0_3 | F1: evidence_quote | G1: evidence_location | H1: why_not_higher | I1: coder_confidence | J1: notes
A2: 3 | B2: 16 | C2: GOV_01 | E2: 2 | F2: “Allianz has established… (DAITAB)… provides recommendations to the Board of Management…”;“The RAI Governance establishes the new role of an AI Trust Officer at both Group and local level.”; “The Group AI Office… providing… AI literacy, and oversight for AI…” | G2: S. 5-6 | H2: Rollen/Gremien + Aufgaben beschrieben. Kein Implementierungsnachweis | I2: Hoch
A3: 3 | B3: 16 | C3: GOV_02 | E3: 1 | F3: “Working cross-functionally, we consult relevant stakeholders… to ensure implementation of… Privacy and Ethics by Design.”; “The Allianz Standard… [and] Functional Rule… establish the… framework… [and] are currently being rolled out.” | G3: S. 2, 6 | H3: Prozessabsicht/Framework erwähnt, keine vollständige Prozesskette. | I3: Mittel
A4: 3 | B4: 16 | C4: GOV_03 | E4: 2 | F4: “perform a dedicated privacy risk assessment whenever personal data are utilised in an AI system.”;“conduct RAI-assessments with the CDO” | G4: S. 4 | H4: Konkrete Checks + Einsatzkontext (Trigger/Verortung). | I4: Hoch
A5: 3 | B5: 16 | C5: GOV_04 | E5: 0 | I5: Hoch
A6: 3 | B6: 16 | C6: GOV_05 | E6: 1 | F6: “The Group AI Office… providing… AI literacy, and oversight for AI…” | G6: S. 6 | H6: Literacy erwähnt, aber keine Pflicht/Programm-Details. | I6: Mittel
A7: 3 | B7: 16 | C7: GOV_06 | E7: 2 | F7: “…escalate unresolved risk disagreements to the DAITAB.” | G7: S. 6 | H7: Eskalationsmechanik benannt, kein Nachweis geübter Abläufe. | I7: Mittel
A8: 3 | B8: 16 | C8: GOV_07 | E8: 0 | I8: Hoch
A9: 4 | B9: 22 | C9: GOV_01 | E9: 1 | F9: “...please contact our Data & AI office.” | G9: S.3 – Contact | H9: „Data & AI office“ als Einheit genannt, aber ohne Aufgaben/RACI. | I9: Hoch
A10: 4 | B10: 22 | C10: GOV_02 | E10: 1 | F10: “BASF maintains a central inventory and conducts necessary assessments to ensure compliance…” | G10: S.1 – „Commitment…“ | H10: Inventory + „assessments“ erwähnt, jedoch ohne Trigger/Owner/Schrittfolge. | I10: Hoch
A11: 4 | B11: 22 | C11: GOV_03 | E11: 1 | F11: “BASF maintains a central inventory and conducts necessary assessments to ensure compliance…” | G11: S.1 – „Commitment…“ | H11: „central inventory“ + „necessary assessments“ (Checks allgemein, nicht spezifiziert). | I11: Hoch
A12: 4 | B12: 22 | C12: GOV_04 | E12: 0 | I12: Hoch | J12: Nicht nachweisbar.
A13: 4 | B13: 22 | C13: GOV_05 | E13: 0 | I13: Hoch | J13: Nicht nachweisbar.
A14: 4 | B14: 22 | C14: GOV_06 | E14: 0 | I14: Hoch | J14: Nicht nachweisbar.
A15: 4 | B15: 22 | C15: GOV_07 | E15: 0 | I15: Hoch | J15: Nicht nachweisbar.
A16: 5 | B16: 27 | C16: GOV_01 | E16: 1 | F16: “...seek advice… including our independent Bioethics Council members.” | G16: S.2 – Our commitments | H16: Bioethics Council erwähnt (Beratung), aber keine AI-spezifischen Rollen/RACI. | I16: Niedrig
A17: 5 | B17: 27 | C17: GOV_02 | E17: 1 | F17: “We regularly cooperate with researchers, regulatory bodies… to jointly develop trustworthy AI-enabled solutions.”; “We hold companies that Bayer partners with… or… procured to the same standard.” | G17: S.8 – AI (Guiding Principles) | H17: „regularly cooperate…“ + Partnerstandard (Prozessabsicht, keine Schrittfolge/Trigger/Owner). | I17: Mittel
A18: 5 | B18: 27 | C18: GOV_03 | E18: 2 | F18: “We verify the data sets used for AI training are representative…”; “We do not use poor, incomplete or non-verified data… incorrect or biased results… AI applications.” | G18: S.8 – AI (Guiding Principles) | H18: Konkrete Checks: Representativeness-Verifikation; Datenverifikation/„do not use“ (ohne Toolname). | I18: Mittel
A19: 5 | B19: 27 | C19: GOV_04 | E19: 1 | F19: “...put into practice… safeguards… internal oversight, inspections, and maintenance of AI solutions.” | G19: S.8 – AI (Guiding Principles) | H19: „inspections“ erwähnt, aber ohne Audit-Mechanik/Frequenz/Verantwortliche. | I19: Niedrig
A20: 5 | B20: 27 | C20: GOV_05 | E20: 0 | I20: Hoch | J20: Nicht nachweisbar.
A21: 5 | B21: 27 | C21: GOV_06 | E21: 0 | I21: Hoch | J21: Nicht nachweisbar.
A22: 5 | B22: 27 | C22: GOV_07 | E22: 0 | I22: Hoch | J22: Nicht nachweisbar.
A23: 6 | B23: 32 | C23: GOV_01 | E23: 0 | I23: hoch | J23: Rollen genannt, aber ohne KI/AI-Bezug → 0.
A24: 6 | B24: 32 | C24: GOV_02 | E24: 0 | I24: hoch | J24: Keine KI-spezifischen Prozesse nachweisbar.
A25: 6 | B25: 32 | C25: GOV_03 | E25: 0 | I25: hoch | J25: Keine KI-spezifischen Checks/Tools nachweisbar.
A26: 6 | B26: 32 | C26: GOV_04 | E26: 0 | I26: hoch | J26: Audit-Begriff nur allgemein/Finanzen, nicht KI/AI-Audits.
A27: 6 | B27: 32 | C27: GOV_05 | E27: 0 | I27: hoch | J27: Training nur allgemein, nicht KI-spezifisch.
