Workbook

Sheet 00_DAX_Master
A1: company_id | B1: company_name_official | C1: brand_short | D1: sector_cluster | E1: industry_detail | F1: hq_country | G1: dax_member_as_of_date | H1: Marktkapitalisierung in Mio. € (Stand: 04.01.2026) | I1: notes_sampling
A2: 1 | B2: Adidas | C2: ADS | D2: Consumer | E2: Sportartikel | F2: Bayern | G2: 22. Juni 1998 | H2: 28070.86 | I2: Trotz intensiver Recherche auf offiziellen Konzernquellen und in Berichten gibt es keine öffentlich zugängliche KI‑Ethik‑ oder Responsible‑AI‑Policy von adidas
A3: 2 | B3: Airbus | C3: AIR | D3: Industrie | E3: Luftfahrt, Raumfahrt, Rüstung | F3: Niederlande | G3: 20. Sep. 2021 | H3: 146046.49 | I3: Keine öffentlichen, dedizierten „Responsible AI Policies“ im Sinne eines separaten Dokuments gefunden; die wichtigsten Aussagen sind in der Human‑rights‑Seite und im Digital‑Ethics‑Kapitel des Verhaltenskodex integriert.
A4: 3 | B4: Allianz | C4: ALV | D4: Finance | E4: Versicherungen | F4: Bayern | G4: 1. Juli 1988 | H4: 138065.08 | I4: Keine dedizierten öffentlichen „Allianz Standard for Responsible AI“‑Dokumente gefunden; der Standard wird nur intern erwähnt.
A5: 4 | B5: BASF | C5: BAS | D5: Materials/Chemicals | E5: Chemie | F5: Rheinland-Pfalz | G5: 1. Juli 1988 | H5: 36934 | I5: Es wurde keine öffentlich zugängliche, eigenständige „Data & AI Policy“ von BASF gefunden. Hinweise auf eine interne Data‑&‑AI‑Policy erscheinen im Responsible‑AI‑Text, sind aber nicht öffentlich abrufbar.
A6: 5 | B6: Bayer | C6: BAYN | D6: Materials/Chemicals | E6: Chemie, Pharma | F6: Nordrhein-Westfalen | G6: 1. Juli 1988 | H6: 33814.35 | I6: Mehrere relevante Dokumente gefunden.
A7: 6 | B7: Beiersdorf | C7: BEI | D7: Consumer | E7: Konsumgüter (Produktion) | F7: Hamburg | G7: 20. Juni 2022 | H7: 19043.54 | I7: Die einzige explizite AI‑Policy‑Aussage stammt aus dem Annual Report 2024. Die Code‑of‑Conduct‑Dokumente und die Human‑Rights‑Policy enthalten relevante Leitplanken zu digitaler Verantwortung, Daten‑ und Menschenrechtsschutz, aber keine spezifischen KI‑Prinzipien
A8: 7 | B8: BMW | C8: BMW | D8: Industrie | E8: Automobil (Produktion) | F8: Bayern | G8: 1. Juli 1988 | H8: 52864.52 | I8: Mehrere relevante Dokumente gefunden.
A9: 8 | B9: Brenntag | C9: BNR | D9: Materials/Chemicals | E9: Chemie (Handel) | F9: Nordrhein-Westfalen | G9: 20. Sep. 2021 | H9: 6654.82 | I9: Es konnten keine spezifischen öffentlichen KI‑Leitlinien oder Responsible‑AI‑Policies von Brenntag SE gefunden werden
A10: 9 | B10: Commerzbank | C10: CBK | D10: Finance | E10: Banken | F10: Hessen | G10: 27. Feb. 2023 | H10: 37853.56 | I10: Die zentrale AI-Quelle ist das Dokument „KI-Grundsätze im Commerzbank-Konzern“
A11: 10 | B11: Continental | C11: CON | D11: Industrie | E11: Automobil (Zulieferer) | F11: Niedersachsen | G11: 24. Sep. 2012 | H11: 12640.94 | I11: Mehrere semi-relevante Dokumente gefunden.
A12: 11 | B12: Daimler Truck | C12: DTG | D12: Industrie | E12: Nutzfahrzeuge (Produktion) | F12: Baden-Württemberg | G12: 21. März 2022 | H12: 25660.46 | I12: Keine eigenständigen, konzernweiten „Responsible AI Policy“ oder „AI Principles“ separat vom Code of Conduct/Integrity Code identifiziert
A13: 12 | B13: Deutsche Bank | C13: DBK | D13: Finance | E13: Banken | F13: Hessen | G13: 1. Juli 1988 | H13: 57682.6 | I13: Die konkretesten AI-Prinzipien lagen öffentlich am klarsten im Supplier Code of Conduct (AI & Data Ethics Principles) sowie Governance-Hinweise (z. B. „AI Oversight Forum“) in ESG/IR-Reports vor; darüber hinaus keine weiteren belastbaren Policy-Dokumente.
... A41: 40 | B41: Zalando | C41: ZAL | D41: Consumer | E41: Versandhandel (Mode) | F41: Berlin | G41: 20. Sep. 2021 | H41: 6113.98 | I41: relevante Inhalte zu KI-/Algorithmus-Werten und Governance sind über CDR-Report, Code of Ethics, ESG- und D&I-Dokumente sowie Tech-Blog-Artikel verteilt.

Sheet 01_Document_Log
A1: doc_id | B1: company_id | C1: doc_title | D1: doc_type | E1: publisher | F1: publication_date | G1: version | H1: language | I1: url | J1: access_date | K1: file_name_local | L1: inclusion_status | M1: exclusion_reason | N1: relevance_notes | O1: Inkludiert in Pilot?
A2: 1 | B2: 1 | C2: Fair Play Code of Conduct | D2: Code of Conduct | E2: adidas AG | F2: n.n. | G2: n.n. | H2: EN | I2: https://www.adidas-group.com/en/investors/corporate-governance/adidas-fair-play-code-of-conduct | J2: 16.02.2026 | K2: 001_01_FairPlayCode_1602026.pdf | L2: Nicht inkudiert | M2: Keine KI Relevanz | N2: Stellt umfassend die ethischen Erwartungen an alle adidas‑Mitarbeitenden dar (Antikorruption, Datenschutz, Verhalten), enthält Governance‑Mechanismen wie Schulungen und Berichtswege. Trotz fehlendem KI‑Bezug ist es das stärkste normative Dokument.
A3: 2 | B3: 1 | C3: Compliance Policy | D3: Code of Conduct | E3: adidas AG | F3: n.n. | G3: n.n. | H3: EN | I3: https://www.adidas-group.com/en/investors/corporate-governance/adidas-fair-play-code-of-conduct | J3: 16.02.2026 | K3: 002_01_compliance_policy_160226.pdf | L3: Nicht inkudiert | M3: Keine KI Relevanz | N3: Erläutert konkret die Regeln zu Bestechung, Geschenken, Betrug, Wettbewerbsrecht und Interessenkonflikten sowie die Pflichten und Verfahren bei Verstößen. Wichtiges Governance‑Rahmenwerk, obwohl keine KI‑Themen adressiert werden.
A4: 3 | B4: 1 | C4: Human Rights Policy | D4: Other | E4: adidas AG | F4: 01.02.2024 | G4: n.n. | H4: EN | I4: https://www.adidas-group.com/en/sustainability/transparency/policies | J4: 16.02.2026 | K4: 003_01_Human_Rights_Policy_160226.pdf | L4: Nicht inkudiert | M4: Keine KI Relevanz | N4: Verankert adidas’ Verpflichtung zu internationalen Menschenrechtsstandards und beschreibt Due‑Diligence‑Prozesse zur Identifizierung und Vermeidung negativer Auswirkungen. Relevante Werte wie Fairness, Gleichheit und Schutz vulnerabler Gruppen können später als Kontext für KI‑Ethik dienen.
A5: 4 | B5: 1 | C5: ETHICAL COMMUNICATION GUIDELINES | D5: Code of Conduct | E5: Adidas Foundation | F5: n.n. | G5: n.n. | H5: EN | I5: https://www.adidasfoundation.org/about/policies-and-guidelines | J5: 16.02.2026 | K5: 004_01_Ethical_comms_guide_160226.pdf | L5: Nicht inkudiert | M5: Keine KI Relevanz
A6: 5 | B6: 1 | C6: Safeguarding Policy | D6: Code of Conduct | E6: Adidas Foundation | F6: n.n. | G6: n.n. | H6: EN | I6: https://www.adidasfoundation.org/about/policies-and-guidelines | J6: 16.02.2026 | K6: 005_SafeguardingPolicy_160226.pdf | L6: Nicht inkudiert | M6: Keine KI Relevanz
A7: 6 | B7: 1 | C7: Supervisory Board Report 2024 | D7: Annual Report | E7: Adidas Group | F7: 01.03.2025 | G7: n.n. | H7: EN | I7: https://report.adidas-group.com/2024/en/to-our-shareholders/supervisory-board-report.html | J7: 16.02.2026 | K7: 006_01_Supervisory_Report_2024_160226.pdf | L7: Nicht inkudiert | M7: Keine KI Relevanz
A8: 7 | B8: 1 | C8: Integrated Management System Global Policy | D8: Sustainability Report | E8: Adidas AG | F8: 01.01.2026 | G8: n.n. | H8: EN | I8: https://www.adidas-group.com/de/nachhaltigkeit/transparenz/richtlinien?tag=Eigene+Standorte | J8: 16.02.2026 | K8: 007_01_IMSGP_160226.pdf | L8: Nicht inkudiert | M8: Keine KI Relevanz
B9: 1 | D9: AI Principles | E9: Adidas AG | L9: Nicht gefunden | N9: No public AI/Responsible AI guideline, policy or principles found (as of 2026‑02‑16)
B10: 1 | D10: AI Policy | E10: Adidas AG | L10: Nicht gefunden | N10: No public AI/Responsible AI guideline, policy or principles found (as of 2026‑02‑16)
B11: 1 | D11: Responsible AI / Ethics | E11: Adidas AG | L11: Nicht gefunden | N11: No public AI/Responsible AI guideline, policy or principles found (as of 2026‑02‑16)
A12: 8 | B12: 2 | C12: Our approach to Artificial Intelligence (AI) | D12: AI Policy | E12: Airbus SE | F12: n.n. | G12: n.n. | H12: EN | I12: https://www.airbus.com/en/sustainability-draft/our-approach-to-sustainability/human-rights | J12: 16.02.2026 | K12: 008_02_AI_Approach_160226 | L12: Inkludiert
A13: 9 | B13: 2 | C13: Airbus Code of Conduct – 2025 Edition | D13: Code of Conduct | E13: Airbus SE | F13: n.n. | G13: n.n. | H13: EN | I13: https://www.airbus.com/sites/g/files/jlcbta136/files/2025-04/2025-Airbus-Code-of-Conduct-EN.pdf | J13: 16.02.2026 | K13: 009_02_Code-of-Conduct_160226.pdf | L13: Inkludiert
A14: 10 | B14: 2 | C14: Airbus Supplier Code of Conduct | D14: Code of Conduct | E14: Airbus SE | F14: n.n. | G14: n.n. | H14: EN | I14: https://www.airbus.com/sites/g/files/jlcbta136/files/2021-07/Airbus-Supplier-Code-of-Conduct.pdf | J14: 16.02.2026 | K14: 010_02_Supplier-Code-of-Conduct_160226.pdf | L14: Nicht inkudiert | M14: Keine KI Relevanz
A15: 11 | B15: 2 | C15: Airbus Ethics & Compliance Anti‑Corruption Policy | D15: Other | E15: Airbus SE | F15: n.n. | G15: n.n. | H15: EN | I15: https://www.airbus.com/sites/g/files/jlcbta136/files/2021-10/Airbus-Ethics-and-Compliance-Anti-Corruption-Policy.pdf | J15: 16.02.2026 | K15: 011_02_Ethics-and-Compliance-Anti-Corruption-Policy_160226.pdf | L15: Nicht inkudiert | M15: Keine KI Relevanz
A16: 12 | B16: 2 | C16: Pioneering sustainable aerospace (Sustainability publication 2025) | D16: Sustainability Report | E16: Airbus SE | F16: 2025 | G16: n.n. | H16: EN | I16: https://www.airbus.com/sites/g/files/jlcbta136/files/2025-04/2025_Airbus_Pioneering_sustainable_aerospace_publication.pdf | J16: 16.02.2026 | K16: 012_02_Pioneering_sustainable_aerospace_publication_160226.pdf | L16: Nicht inkudiert | M16: Keine KI Relevanz
A17: 13 | B17: 2 | C17: Airbus Summit 2025 – Harnessing the power of responsible AI | D17: Press Release | E17: Airbus SE | F17: 25.03.2025 | G17: n.n. | H17: EN | I17: https://www.airbus.com/en/airbus-summit-2025/harnessing-the-power-of-responsible-ai | J17: 16.02.2026 | K17: 013_02_Harnessing the power of responsible AI _160226pdf | L17: Nicht inkudiert | M17: PR ohne normative Substanz
A18: 14 | B18: 2 | C18: Information Notice of the 2025 Annual General Meeting | D18: Annual Report | E18: Airbus SE | F18: 15.04.2025 | G18: n.n. | I18: https://www.airbus.com/sites/g/files/jlcbta136/files/2025-03/information_notice.pdf | J18: 16.02.2026 | K18: 014_02_Annual_General_Meeting_2025_160226.pdf | L18: Nicht inkudiert | M18: Keine KI Relevanz
A19: 15 | B19: 2 | C19: Artificial Intelligence | D19: Website Page | E19: Airbus SE | F19: n.n. | G19: n.n. | H19: EN | I19: https://www.airbus.com/en/innovation/digital-transformation/artificial-intelligence | J19: 16.02.2026 | K19: 015_02_AI_Website_160226 | L19: Nicht inkudiert | M19: PR ohne normative Substanz | N19: Kein Bezug zur KI Ethikrichtlinien; beschreibt nur technischen/ wirtschaftlichen Einsatz von KI
B20: 2 | D20: AI Principles | E20: Airbus SE | L20: Nicht gefunden | N20: No public AI/Responsible AI guideline or principles found (as of 2026‑02‑16)
B21: 2 | D21: Responsible AI / Ethics | E21: Airbus SE | L21: Nicht gefunden | N21: No public AI/Responsible AI guideline or principles found (as of 2026‑02‑16)
A22: 16 | B22: 3 | C22: Responsible Use of Artificial Intelligence (AI) | D22: Responsible AI / Ethics | E22: Allianz SE | F22: n.n. | G22: n.n. | H22: EN | I22: https://www.allianz.com/en/about-us/strategy-values/responsible-use-of-artificial-intelligence.html | J22: 16.02.2026 | K22: 016_03_Responsible Use of Artificial Intelligence_160226.pdf | L22: Inkludiert | O22: X
A23: 17 | B23: 3 | C23: Allianz Code of Conduct | D23: Code of Conduct | E23: Allianz SE | F23: 2025 | G23: n.n. | H23: EN | I23: https://www.allianz.com/content/dam/onemarketing/azcom/Allianz_com/about-us/strategy-values/compliance/code-of-conduct/code-of-conduct-accessible.pdf | J23: 16.02.2026 | K23: 017_03_code-of-conduct_160226.pdf | L23: Inkludiert | O23: X
A24: 18 | B24: 3 | C24: Privacy Statement – Data Ethics section | D24: Other | E24: Allianz SE | F24: 2025 | G24: n.n. | H24: EN | I24: https://www.allianz.com/en/privacy-statement.html | J24: 16.02.2026 | K24: 018_03_Privacy Statement_160226.pdf | L24: Inkludiert
A25: 19 | B25: 3 | C25: Allianz Privacy Standard – Public Version | D25: Other | E25: Allianz SE | F25: 43221 | G25: 1.0 | H25: EN | I25: https://www.allianzgloballife.com/content/dam/onemarketing/azgl/allianzgloballife/doc/31122019/en_gb/Allianz-Privacy-Standard_PUBLIC_EN.pdf | J25: 16.02.2026 | K25: 019_03_Privacy-Standard_PUBLIC_EN_160226.pdf | L25: Nicht inkudiert | M25: Duplikat / Veraltete Version
A26: 20 | B26: 3 | C26: Allianz Group Sustainability Report 2023 – Data ethics/AI governance sections | D26: Sustainability Report | E26: Allianz SE | F26: 2023 | G26: n.n. | H26: EN | I26: https://www.allianz.com/content/dam/onemarketing/azcom/Allianz_com/sustainability/documents/Allianz_Group_Sustainability_Report_2023-web.pdf | J26: 16.02.2026 | K26: 020_03_Sustainability_Report_2023_160226.pdf | L26: Nicht inkudiert | M26: Duplikat / Veraltete Version
A27: 21 | B27: 3 | C27: Responsible AI: a sustainable approach to transformative technology | D27: Responsible AI / Ethics | E27: Allianz Global Investors (subsidiary) | F27: n.n. | G27: n.n. | H27: EN | I27: https://www.allianzgi.com/documents/Responsible-AI-a-sustainable-approach-to-transformative-technology | J27: 16.02.2026 | K27: 021_03_Responsible_AI_160226.pdf | L27: Inkludiert | N27: Tochtergesellschaft der Allianz SE
B28: 3 | D28: AI Principles | E28: Allianz SE | L28: Nicht gefunden | N28: No public AI policy or principles found (as of 2026‑02‑16)
B29: 3 | D29: AI Policy | E29: Allianz SE | L29: Nicht gefunden | N29: No public AI policy or principles found (as of 2026‑02‑16)
A30: 22 | B30: 4 | C30: Responsible AI at BASF | D30: Responsible AI / Ethics | E30: BASF SE | F30: n.n. | G30: n.n. | H30: EN | I30: https://www.basf.com/global/en/who-we-are/digitalization/artificial-intelligence/Responsible-AI-at-BASF | J30: 16.02.2026 | K30: 022_04_Responsible_AI_160226.pdf | L30: Inkludiert | O30: X
A31: 23 | B31: 4 | C31: BASF Code of Conduct | D31: Code of Conduct | E31: BASF SE | F31: n.n. | G31: n.n. | H31: EN | I31: https://www.basf.com/dam/jcr:0304db1d-bcbb-3015-a965-62627c1b61d2/basf/www/global/documents/en/investor-relations/calendar-and-publications/reports/2025/BASF_Code-of-Conduct.pdf | J31: 16.02.2026 | K31: 023_04_Code-of-Conduct_160226.pdf | L31: Inkludiert | O31: X
A32: 24 | B32: 4 | C32: Data protection @ BASF – Data processing in the BASF Group | D32: Other | E32: BASF SE | F32: n.n. | G32: n.n. | H32: EN | I32: https://www.basf.com/global/en/legal/data-protection-at-basf | J32: 16.02.2026 | K32: 024_04_Data protection_160226.pdf | L32: Inkludiert
A33: 25 | B33: 4 | C33: BASF Group’s Policy Statement on Human Rights | D33: Other | E33: BASF SE | F33: n.n. | G33: n.n. | H33: EN | I33: https://www.basf.com/dam/jcr:4944a24f-defc-4987-9dd6-d38dba24efd9/basf/www/global/documents/en/sustainability/we-value-people-and-treat-them-with-respect/human-rights/Human-Rights-Policy-Statement-BASF-Group.pdf | J33: 16.02.2026 | K33: 025_04_Human-Rights-Policy-Statement_160226.pdf | L33: Nicht inkudiert | M33: Keine KI Relevanz
A34: 26 | B34: 4 | C34: Supplier Code of Conduct (Version 2024) | D34: Code of Conduct | E34: BASF SE | F34: 45474 | G34: n.n. | H34: EN | I34: https://www.basf.com/dam/jcr:83c0af8a-4e46-37c0-945f-3fd15ff4fca3/basf/www/global/documents/en/about-us/suppliers-and-partners/supplier-code-of-conduct/Supplier_Code_of_conduct_Version%202024%20-%20English.pdf | J34: 16.02.2026 | K34: 025_04_Supplier_Code_of_conduct_160226.pdf | L34: Nicht inkudiert | M34: Keine KI Relevanz
B35: 4 | D35: AI Principles | E35: BASF SE | L35: Nicht gefunden | N35: No public AI policy or principles found (as of 2026‑02‑16)
B36: 4 | D36: AI Policy | E36: BASF SE | L36: Nicht gefunden | N36: No public AI policy or principles found (as of 2026‑02‑16)
A37: 27 | B37: 5 | C37: Bioethical Principles – AI in the context of human healthcare | D37: AI Principles | E37: Bayer AG | F37: n.n. | G37: n.n. | H37: EN | I37: https://www.bayer.com/en/sustainability/bioethical-principles | J37: 16.02.2026 | K37: 027_05_Bioethical Principles_160226.pdf | L37: Inkludiert | O37: X
A38: 28 | B38: 5 | C38: Generative Artificial Intelligence (GenAI) Guidance and Rules – version 3 | D38: AI Policy | E38: Bayer AG | F38: 17.10.2024 | G38: V3 | H38: EN | I38: https://idnet.bayer.com/sites/idnet/files/final-en-genai-guidelines-and-rules-v3.pdf | J38: 16.02.2026 | K38: 028_05_genai-guidelines_160226.pdf | L38: Inkludiert | O38: X
A39: 29 | B39: 5 | C39: Our Code of Conduct – Responsible use of Artificial Intelligence section | D39: Code of Conduct | E39: Bayer AG | F39: n.n. | G39: n.n. | H39: EN | I39: https://www.bayer.com/en/commitments/code-of-conduct | J39: 16.02.2026 | K39: 029_05_Code of Conduct_160226.pdf | L39: Nicht inkudiert | M39: Keine KI Relevanz | N39: Update: 15. März 26: doch kein KI-Bezug & nun exkludiert
A40: 30 | B40: 5 | C40: Unleashing the Potential of AI – AI Ethics and Responsibility section | D40: Responsible AI / Ethics | E40: Bayer AG | F40: n.n. | G40: n.n. | H40: EN | I40: https://www.bayer.com/en/innovation/unleashing-the-potential-of-ai | J40: 16.02.2026 | K40: 030_05_Unleashing the Potential of AI_160226.pdf | L40: Inkludiert
...

Sheet 02_Values_Codebook
A1: value_id | B1: value_name | C1: definition_short | D1: include_rules | E1: exclude_rules | F1: synonyms_terms | G1: example_phrases | H1: notes_boundary_cases
A2: VAL_01 | B2: Human Agency & Oversight | C2: Menschen behalten Kontrolle/Überwachung über KI | D2: Wenn menschliche Kontrolle/Override/Review explizit gefordert | E2: Reine Floskel „human-centered“ ohne Mechanik | F2: human oversight; human-in-the-loop; human control; override; review | G2: human review; override; escalation to humans | H2: Unterscheide Wert vs Governance-Kriterium 'Eskalationswege'
A3: VAL_02 | B3: Accountability & Responsibility | C3: Zuständigkeit/Verantwortung für KI-Entscheidungen/Outcomes | D3: Wenn Verantwortliche Rollen/Verantwortungsprinzip genannt | E3: Reines „we take responsibility“ ohne Bezug zu KI | F3: responsibility; accountability; ownership; governance | G3: clear accountability; responsible for AI | H3: Kann mit GOV_01 (Zuständigkeiten) kollidieren – hier nur als Wert codieren
A4: VAL_03 | B4: Transparency | C4: Nachvollziehbarkeit über Einsatz/Zweck/Entscheidungslogik | D4: Wenn Transparenzpflichten oder Offenlegung zu KI erwähnt | E4: Transparenz nur im Sinne von „Kommunikation“ ohne KI-Bezug | F4: transparency; disclosure; openness | G4: transparent use of AI; disclose AI involvement | H4: VAL_03 codieren, wenn Offenlegung, Identifizierbarkeit oder der Einsatz von KI gemeint ist (z. B. disclose AI involvement, AI system identifiable). Nicht als VAL_04 codieren, solange keine Erklärung/Interpretierbarkeit von Output, Modell oder Entscheidungslogik gefordert wird.
A5: VAL_04 | B5: Explainability | C5: Erklärbarkeit von KI-Entscheidungen/Outputs | D5: Wenn Erklärbarkeit, Interpretierbarkeit oder Verständlichkeit von KI-Output oder Entscheidungslogik gefordert wird; dazu zählen auch Formulierungen wie "comprehensible decision-making processes" oder die Vermeidung von "black boxes", sofern sie auf Verstehbarkeit/Erklärung und nicht nur auf Offenlegung zielen. | E5: „transparent“ ohne Erklärkomponente | F5: explainability; interpretability; explanation | G5: provide explanations; explain model outputs | H5: Technisch vs kommunikativ – beide zählen
A6: VAL_05 | B6: Fairness & Non-Discrimination | C6: Vermeidung unfairer Benachteiligung/Bias | D6: Wenn Bias/Benachteiligung/Anti-Diskriminierung bei KI genannt | E6: Allgemeine Diversity-Statements ohne KI-Bezug | F6: fairness; bias mitigation; non-discrimination; equity | G6: avoid bias; non-discriminatory outcomes | H6: Achtung: Legal Compliance ist VAL_14, nicht hier
A7: VAL_06 | B7: Privacy & Data Protection | C7: Schutz personenbezogener Daten/Datensparsamkeit | D7: Wenn Datenschutz bei KI/Training/Use erwähnt | E7: Datenschutz rein allgemein ohne KI-Kontext | F7: privacy; data protection; GDPR; data minimization | G7: privacy by design; data minimization | H7: Kann auch als Governance (Tools/Checks) auftauchen – hier Wert
A8: VAL_07 | B8: Security & Cybersecurity | C8: Schutz vor Angriffen/Manipulation/Leakage | D8: Wenn Security für KI-Systeme oder Daten betont | E8: Allgemeine IT-Security ohne KI-Kontext (Grenzfall) | F8: security; cybersecurity; adversarial; secure-by-design | G8: protect against attacks; secure systems | H8: Grenzfall: Wenn nur IT allgemein -> evtl. nicht codieren
A9: VAL_08 | B9: Safety & Harm Prevention | C9: Vermeidung von Schäden (physisch, psychisch, sozial) | D9: Wenn Risiko/Schadensvermeidung durch KI erwähnt | E9: Nur „safe“ als Marketingwort | F9: safety; harm prevention; risk reduction | G9: avoid harm; safe AI | H9: VAL_08 zusätzlich zu VAL_09 codieren, wenn Schäden, unbeabsichtigte Folgen, Missbrauch oder Safety explizit benannt sind. Reine Robustheits-/Zuverlässigkeitsrhetorik ohne Harm-/Safety-Anker bleibt nur VAL_09.
A10: VAL_09 | B10: Technical Robustness & Reliability | C10: Zuverlässigkeit, Stabilität, Fehlerresistenz | D10: Wenn Robustheit, Zuverlässigkeit, Genauigkeit, Testing oder Monitoring ausdrücklich auf das Erreichen intendierter Ergebnisse, Fehlerresistenz oder stabile Funktion von KI zielen. Bloßes Monitoring/Feedback ohne Bezug zu Output-Qualität oder intended outcome reicht nicht. | E10: Reine Qualitätsfloskel ohne Bezug | F10: robustness; reliability; resilience; testing | G10: robust and reliable; tested systems | H10: Kann in GOV_03 (Tools/Checks) konkret werden
A11: VAL_10 | B11: Contestability & Redress | C11: Anfechtbarkeit, Beschwerde, Wiedergutmachung | D11: Wenn Betroffene Einspruch/Review/Redress bei KI-Entscheidungen haben | E11: Reine Customer-Service Aussagen ohne KI | F11: appeal; contest; redress; complaint | G11: right to contest; grievance mechanism | H11: Stark verwandt mit GOV_06 (Eskalation) – hier Wert
A12: VAL_11 | B12: Inclusiveness & Accessibility | C12: Einbezug/Barrierefreiheit/Teilhabe | D12: Wenn KI inklusiv/zugänglich gestaltet werden soll | E12: Allgemeine DEI-/HR-Aussagen ohne KI-Bezug ausschließen. Ebenfalls ausschließen: "inclusion in data sets", repräsentative Daten oder Bias-Minderung ohne Bezug zu Accessibility, Teilhabe oder inklusivem Design; diese Fälle primär unter VAL_05 und/oder VAL_16 prüfen. | F12: accessibility; inclusiveness; participation | G12: inclusive design; accessible AI | H12: Wenn nur HR-DEI -> eher raus
... A19: VAL_18 | B19: Human Rights | C19: Menschenrechte als Rahmen (UNGP etc.) | D19: Wenn Menschenrechte, dignity, UDHR/UNGP oder einzelne Rechte ausdrücklich als Menschenrechtsrahmen für KI genannt werden; Privacy zählt zusätzlich als VAL_18 nur dann, wenn sie explizit als human right oder im Human-Rights-Framework verankert wird. | E19: Allgemeine Werte ohne Human-Rights-Bezug | F19: human rights; dignity; UNGP | G19: respect human rights; protect dignity | H19: Nicht jedes Doc wird das haben – ok

Sheet 04_Governance_Codebook
A1: gov_crit_id | B1: criterion_name | C1: score_0_definition | D1: score_1_definition | E1: score_2_definition | F1: score_3_definition | G1: evidence_minimum | H1: typical_evidence_terms
A2: GOV_01 | B2: Zuständigkeiten | C2: Keine Rollen/Zuständigkeiten genannt | D2: AI-bezogene Rolle, Einheit oder Ownership grob benannt (z. B. AI office, ethics committee, clear accountability/ownership), aber ohne ausdifferenzierte Aufgaben- oder Freigabelogik. | E2: Konkrete Rollen+Aufgaben beschrieben (Owner, Approver, RACI) | F2: Implementiert: Verantwortlichkeiten mit Reporting/Regelterminen/Belegen | G2: Rollentitel + klarer Bezug zu KI/AI-Governance | H2: owner; accountability; committee; board; RACI
A3: GOV_02 | B3: Prozesse | C3: Kein Prozess erwähnt | D3: Prozessabsicht erwähnt (z.B. 'we review AI') | E3: Prozessschritte beschrieben (Lifecycle, Gateways, Freigaben) | F3: Implementiert: Prozess mit Nachweisen (KPIs, regelmäßige Reviews, Prozessdokumente) | G3: Mind. ein Prozessschritt + Trigger + Verantwortliche | H3: AI lifecycle; approval; review; gating; SOP
A4: GOV_03 | B4: Tools/Checks | C4: Keine Checks/Tools | D4: Checks allgemein erwähnt (z.B. 'risk assessment') | E4: Konkreter Check/Mechanismus dokumentiert; der Toolname ist nicht zwingend, wenn Checktyp, Prüfgegenstand und Einsatzzeitpunkt/Anlass erkennbar sind (z. B. representativeness verification, impact assessment, extensive testing, documented monitoring). | F4: Implementiert: Tooling im Betrieb + Pflicht/Protokoll + Ergebnisse berichtet | G4: Name des Tools ODER klar benannter Checktyp/Assessment + Prüfgegenstand + wann/wofür eingesetzt. | H4: bias test; model card; DPIA; validation; monitoring
A5: GOV_04 | B5: Audits | C5: Keine Audits | D5: Audit, Assessment, inspection oder evaluation als Aktivität erwähnt, aber ohne Mechanik/Frequenz/Verantwortliche. Ein bloßes Qualitätsattribut wie "auditable" reicht nicht. | E5: Audit-Mechanik beschrieben (intern/extern, Frequenz) | F5: Implementiert: Auditberichte/KPIs/Review-Zyklen nachweisbar | G5: Auditart + Frequenz oder Verantwortliche | H5: audit; assurance; internal control; external review
A6: GOV_05 | B6: Schulungen | C6: Keine Trainings | D6: Awareness, education oder training ausdrücklich angekündigt, empfohlen oder bereitgestellt; ohne Zielgruppe, Pflichtgrad oder Programmstruktur bleibt Score 1. | E6: Trainingsprogramm beschrieben (Zielgruppe, Inhalte, Pflichtgrad) | F6: Implementiert: Pflichttrainings + Nachweis (Completion, LMS, KPIs) | G6: Mind. Zielgruppe + Pflicht/Regelmäßigkeit | H6: training; awareness; mandatory; LMS; certification
A7: GOV_06 | B7: Eskalationswege | C7: Keine Eskalation | D7: Kontakt/Ansprechpartner genannt | E7: Konkreter Eskalationsprozess beschrieben (Stufen, Fristen) | F7: Implementiert: geübter Prozess/Case-Handling/Reporting | G7: Stufenlogik oder Mechanik (Ticket, Hotline, Committee) | H7: escalation; grievance; hotline; incident; ticket
A8: GOV_07 | B8: Reporting | C8: Kein Reporting | D8: Explizite Reporting-/Disclosure-Absicht zu AI-Risiken, Kontrollen oder Vorfällen erwähnt. Bloße Beratungsempfehlungen an ein Gremium ohne Reportgegenstand zählen nicht. | E8: Reporting-Struktur beschrieben (Was, an wen, wie oft) | F8: Implementiert: regelmäßige Reports/KPIs öffentlich oder intern belegt | G8: KPI/Reportgegenstand + Empfänger + Frequenz | H8: reporting; KPI; dashboard; disclosure; metrics

Sheet 03_Values_Coding
A1: company_id | B1: doc_id | C1: value_id | D1: value_present | E1: binding_level | F1: binding_justification | G1: evidence_quote | H1: evidence_location | I1: coder_confidence | J1: notes | K1: value_points
A2: 2 | B2: 8 | C2: VAL_01 | D2: 1 | E2: 1 | F2: Menschliche Aufsicht über KI wird als essenziell beschrieben. | G2: “Human oversight of AI systems is essential”; “override AI decisions when necessary” | H2: S. 5, Our approach to Artificial Intelligence (AI) | I2: hoch | J2: Explizite menschliche Aufsicht und Override; Prinzipienebene | K2: =Tabelle5[[#This Row],[value_present]]*Tabelle5[[#This Row],[binding_level]] -> 1
A3: 2 | B3: 8 | C3: VAL_02 | D3: 1 | E3: 1 | F3: Airbus beansprucht Verantwortung und will transparente sowie erklärbare KI-Systeme gestalten. | G3: “takes responsibility for their function and consequences” | H3: S. 5, Our approach to Artificial Intelligence (AI) | I3: hoch | J3: Verantwortung für Funktion und Folgen von KI klar benannt | K3: =Tabelle5[[#This Row],[value_present]]*Tabelle5[[#This Row],[binding_level]] -> 1
A4: 2 | B4: 8 | C4: VAL_03 | D4: 1 | E4: 1 | F4: Transparenz und Erklärbarkeit werden gemeinsam genannt. | G4: “designing transparent and explainable systems” | H4: S. 5, Our approach to Artificial Intelligence (AI) | I4: hoch | J4: Transparenz explizit im KI-Abschnitt | K4: =Tabelle5[[#This Row],[value_present]]*Tabelle5[[#This Row],[binding_level]] -> 1
A5: 2 | B5: 8 | C5: VAL_04 | D5: 1 | E5: 1 | F5: Transparenz und Erklärbarkeit werden gemeinsam genannt. | G5: “designing transparent and explainable systems” | H5: S. 5, Our approach to Artificial Intelligence (AI) | I5: hoch | J5: „explainable systems“ explizit | K5: =Tabelle5[[#This Row],[value_present]]*Tabelle5[[#This Row],[binding_level]] -> 1
A6: 2 | B6: 8 | C6: VAL_05 | D6: 1 | E6: 1 | F6: KI soll fair und diskriminierungsfrei sein. | G6: “fairness for all, without discrimination” | H6: S. 5, Our approach to Artificial Intelligence (AI) | I6: hoch | J6: Fairness und Nicht-Diskriminierung explizit | K6: =Tabelle5[[#This Row],[value_present]]*Tabelle5[[#This Row],[binding_level]] -> 1
A7: 2 | B7: 8 | C7: VAL_06 | D7: 1 | E7: 1 | F7: Datenschutz und Data Governance werden als Standards genannt. | G7: “adheres to strict data privacy and governance standards” | H7: S. 5, Our approach to Artificial Intelligence (AI) | I7: hoch | J7: Datenschutz explizit genannt | K7: =Tabelle5[[#This Row],[value_present]]*Tabelle5[[#This Row],[binding_level]] -> 1
A8: 2 | B8: 8 | C8: VAL_07 | D8: 0 | I8: hoch | J8: Kein expliziter KI-Sicherheits-/Cybersecurity-Anker | K8: =Tabelle5[[#This Row],[value_present]]*Tabelle5[[#This Row],[binding_level]] -> 0
A9: 2 | B9: 8 | C9: VAL_08 | D9: 1 | E9: 1 | F9: Sicherheit, Zuverlässigkeit und Schutz vor Schäden werden als KI-Prinzip gesetzt. | G9: “Safety is our top priority” | H9: S. 5, Our approach to Artificial Intelligence (AI) | I9: hoch | J9: Safety-first-Prinzip mit Schutzbezug | K9: =Tabelle5[[#This Row],[value_present]]*Tabelle5[[#This Row],[binding_level]] -> 1
A10: 2 | B10: 8 | C10: VAL_09 | D10: 1 | E10: 1 | F10: Airbus betont Zuverlässigkeit und Verlässlichkeit von KI-Systemen. | G10: “highest standards of reliability and dependability” | H10: S. 5, Our approach to Artificial Intelligence (AI) | I10: hoch | J10: Reliability/Dependability explizit | K10: =Tabelle5[[#This Row],[value_present]]*Tabelle5[[#This Row],[binding_level]] -> 1
A11: 2 | B11: 8 | C11: VAL_10 | D11: 0 | I11: hoch | J11: Kein Einspruchs-, Beschwerde- oder Redress-Mechanismus | K11: =Tabelle5[[#This Row],[value_present]]*Tabelle5[[#This Row],[binding_level]] -> 0
A12: 2 | B12: 8 | C12: VAL_11 | D12: 0 | I12: mittel | J12: „diversity and inclusion“ erscheint eher als Fairness-Unterstützung, nicht als Accessibility/inklusive Gestaltung | K12: =Tabelle5[[#This Row],[value_present]]*Tabelle5[[#This Row],[binding_level]] -> 0
A13: 2 | B13: 8 | C13: VAL_12 | D13: 1 | E13: 1 | F13: KI wird mit planetärer Verantwortung und Prosperität verknüpft. | G13: “enhance societal wellbeing”; “contribute to our sustainability goals by respecting the planet” | H13: S. 5, Our approach to Artificial Intelligence (AI) | I13: hoch | J13: Nachhaltigkeit/Planet explizit im KI-Kontext | K13: =Tabelle5[[#This Row],[value_present]]*Tabelle5[[#This Row],[binding_level]] -> 1
A14: 2 | B14: 8 | C14: VAL_13 | D14: 1 | E14: 1 | F14: Sozialnutzen explizit | G14: “enhance societal wellbeing” | H14: S. 5, Our approach to Artificial Intelligence (AI) | I14: hoch | J14: „societal wellbeing“ explizit | K14: =Tabelle5[[#This Row],[value_present]]*Tabelle5[[#This Row],[binding_level]] -> 1
A15: 2 | B15: 8 | C15: VAL_14 | D15: 1 | E15: 1 | F15: Airbus verankert KI ausdrücklich in einem menschenrechtlichen und IHL-bezogenen Rahmen. | G15: “integrating respect for human rights and adherence to International Humanitarian Law (IHL)” | H15: S. 5, Our approach to Artificial Intelligence (AI) | I15: mittel | J15: IHL-Adhärenz im KI-Kontext, aber ohne deontische Regel | K15: =Tabelle5[[#This Row],[value_present]]*Tabelle5[[#This Row],[binding_level]] -> 1
A16: 2 | B16: 8 | C16: VAL_15 | D16: 0 | I16: mittel | J16: „trustworthy AI“ / „ethics by design“ bleibt hier zu allgemein, keine klare ethische Grenze/Do-not-Regel | K16: =Tabelle5[[#This Row],[value_present]]*Tabelle5[[#This Row],[binding_level]] -> 0
A17: 2 | B17: 8 | C17: VAL_16 | D17: 0 | I17: mittel | J17: „data privacy and governance standards“ ohne Datenqualitäts-, Lineage- oder Stewardship-Anker | K17: =Tabelle5[[#This Row],[value_present]]*Tabelle5[[#This Row],[binding_level]] -> 0
A18: 2 | B18: 8 | C18: VAL_17 | D18: 0 | I18: hoch | J18: Kein expliziter KI-bezogener IP-/Confidentiality-Bezug | K18: =Tabelle5[[#This Row],[value_present]]*Tabelle5[[#This Row],[binding_level]] -> 0
A19: 2 | B19: 8 | C19: VAL_18 | D19: 1 | E19: 1 | F19: Airbus verankert KI ausdrücklich in einem menschenrechtlichen und IHL-bezogenen Rahmen. | G19: “integrating respect for human rights and adherence to International Humanitarian Law (IHL)” | H19: S. 5, Our approach to Artificial Intelligence (AI) | I19: hoch | J19: Menschenrechte explizit als KI-Rahmen genannt | K19: =Tabelle5[[#This Row],[value_present]]*Tabelle5[[#This Row],[binding_level]] -> 1
A20: 2 | B20: 9 | C20: VAL_01 | D20: 1 | E20: 2 | F20: Negative Begrenzung menschlich sensibler Entscheidungen | G20: “Use artificial intelligence to make decisions about personal, moral or political issues.” | H20: S. 31, Digital Ethics | I20: mittel | J20: Verbot KI-Entscheidungen in personal/moral/political issues; kein expliziter Override, aber klare normative Begrenzung | K20: =Tabelle5[[#This Row],[value_present]]*Tabelle5[[#This Row],[binding_level]] -> 2
A21: 2 | B21: 9 | C21: VAL_02 | D21: 0 | I21: mittel | J21: „responsibly“ zu allgemein; keine klare Verantwortungszurechnung für KI-Folgen | K21: =Tabelle5[[#This Row],[value_present]]*Tabelle5[[#This Row],[binding_level]] -> 0
A22: 2 | B22: 9 | C22: VAL_03 | D22: 1 | E22: 2 | F22: Nutzer sollen bei KI-Systemen informiert werden; Zwecke, Inputs und Outputs sollen erklärt werden. | G22: “without informing the users, and without explaining its purposes, inputs and outputs” | H22: S. 31, Digital Ethics | I22: hoch | J22: Nutzerinformation über KI-Systeme explizit als Negativbeispiel | K22: =Tabelle5[[#This Row],[value_present]]*Tabelle5[[#This Row],[binding_level]] -> 2
A23: 2 | B23: 9 | C23: VAL_04 | D23: 1 | E23: 2 | F23: Nutzer sollen bei KI-Systemen informiert werden; Zwecke, Inputs und Outputs sollen erklärt werden. | G23: “without informing the users, and without explaining its purposes, inputs and outputs” | H23: S. 31, Digital Ethics | I23: hoch | J23: Zwecke, Inputs und Outputs sollen erklärt werden | K23: =Tabelle5[[#This Row],[value_present]]*Tabelle5[[#This Row],[binding_level]] -> 2
A24: 2 | B24: 9 | C24: VAL_05 | D24: 1 | E24: 3 | F24: Fairness explizit; zugleich Prozesshinweis | G24: “Regularly review artificial intelligence systems to ensure fairness and prevent biases.” | H24: S. 31, Digital Ethics | I24: hoch | J24: Regelmäßige KI-Reviews zur Fairness-/Bias-Prävention = prozessuale Operationalisierung | K24: =Tabelle5[[#This Row],[value_present]]*Tabelle5[[#This Row],[binding_level]] -> 3
A25: 2 | B25: 9 | C25: VAL_06 | D25: 1 | E25: 2 | F25: Expliziter Human-Rights- und Privacy-Bezug; Privacy/Data protection explizit | G25: “This includes respecting human rights and privacy.”; “Take measures to protect the personal information we manage and share.” | H25: S. 31, Digital Ethics | I25: hoch | J25: Privacy explizit; Schutz persönlicher Informationen klar normiert | K25: =Tabelle5[[#This Row],[value_present]]*Tabelle5[[#This Row],[binding_level]] -> 2
A26: 2 | B26: 9 | C26: VAL_07 | D26: 0 | I26: hoch | J26: Security-Kapitel ist nicht KI-spezifisch; kein KI-Anker | K26: =Tabelle5[[#This Row],[value_present]]*Tabelle5[[#This Row],[binding_level]] -> 0
A27: 2 | B27: 9 | C27: VAL_08 | D27: 0 | I27: hoch | J27: Kein expliziter KI-Safety-Bezug im Digital-Ethics-Abschnitt | K27: =Tabelle5[[#This Row],[value_present]]*Tabelle5[[#This Row],[binding_level]] -> 0
A28: 2 | B28: 9 | C28: VAL_09 | D28: 0 | I28: hoch | J28: Keine Robustness-/Reliability-Aussage zu KI | K28: =Tabelle5[[#This Row],[value_present]]*Tabelle5[[#This Row],[binding_level]] -> 0
A29: 2 | B29: 9 | C29: VAL_10 | D29: 0 | I29: hoch | J29: Kein KI-spezifischer Einspruchs- oder Redress-Mechanismus | K29: =Tabelle5[[#This Row],[value_present]]*Tabelle5[[#This Row],[binding_level]] -> 0
A30: 2 | B30: 9 | C30: VAL_11 | D30: 0 | I30: mittel | J30: Allgemeine Inclusion-/Diversity-Passage ohne KI-Anker | K30: =Tabelle5[[#This Row],[value_present]]*Tabelle5[[#This Row],[binding_level]] -> 0
A31: 2 | B31: 9 | C31: VAL_12 | D31: 1 | E31: 1 | F31: Nachhaltigkeits-/Wohlfahrtsbezug, aber breit formuliert | G31: “We leverage digital technologies to help meet our sustainability goals.” | H31: S. 31, Digital Ethics | I31: mittel | J31: Digitaltechnologien zur Unterstützung von Nachhaltigkeitszielen erwähnt, aber sehr allgemein | K31: =Tabelle5[[#This Row],[value_present]]*Tabelle5[[#This Row],[binding_level]] -> 1
A32: 2 | B32: 9 | C32: VAL_13 | D32: 0 | I32: mittel | J32: Kein expliziter societal wellbeing-/public benefit-Anker im KI-Kontext | K32: =Tabelle5[[#This Row],[value_present]]*Tabelle5[[#This Row],[binding_level]] -> 0
A33: 2 | B33: 9 | C33: VAL_14 | D33: 1 | E33: 2 | F33: Klarer KI-/Digital-Anker; normativer Grundsatz | G33: “using digital technologies legally, responsibly and ethically” | H33: S. 31, Digital Ethics | I33: hoch | J33: „legally“ im Digital-/KI-Kontext als klare Norm | K33: =Tabelle5[[#This Row],[value_present]]*Tabelle5[[#This Row],[binding_level]] -> 2
A34: 2 | B34: 9 | C34: VAL_15 | D34: 1 | E34: 2 | F34: Klarer KI-/Digital-Anker; normativer Grundsatz | G34: “using digital technologies legally, responsibly and ethically” | H34: S. 31, Digital Ethics | I34: hoch | J34: „ethically“ explizit; normative Verwendungsregel | K34: =Tabelle5[[#This Row],[value_present]]*Tabelle5[[#This Row],[binding_level]] -> 2
A35: 2 | B35: 9 | C35: VAL_16 | D35: 0 | I35: mittel | J35: Keine Datenqualitäts- oder Data-Governance-Mechanik | K35: =Tabelle5[[#This Row],[value_present]]*Tabelle5[[#This Row],[binding_level]] -> 0
A36: 2 | B36: 9 | C36: VAL_17 | D36: 0 | I36: hoch | J36: Kein KI-spezifischer IP-/Confidentiality-Bezug | K36: =Tabelle5[[#This Row],[value_present]]*Tabelle5[[#This Row],[binding_level]] -> 0
A37: 2 | B37: 9 | C37: VAL_18 | D37: 1 | E37: 2 | F37: Expliziter Human-Rights- und Privacy-Bezug | G37: “This includes respecting human rights and privacy.” | H37: S. 31, Digital Ethics | I37: hoch | J37: Menschenrechte explizit einbezogen | K37: =Tabelle5[[#This Row],[value_present]]*Tabelle5[[#This Row],[binding_level]] -> 2
A38: 3 | B38: 16 | C38: VAL_01 | D38: 1 | E38: 2 | F38: Allianz nennt einen human-centric Ansatz und konsultiert relevante Stakeholder. | G38: “We are implementing a human centric approach to AI.”; “must respect customers’ autonomy and decision-making”; “We ensure an appropriate, risk-based level of human control.” | H38: S. 2; S. 5, RAI approach / Prinzip 8 Human Oversight | I38: hoch | J38: Human-centric approach, Kundenautonomie und human control klar normiert | K38: =Tabelle5[[#This Row],[value_present]]*Tabelle5[[#This Row],[binding_level]] -> 2
A39: 3 | B39: 16 | C39: VAL_02 | D39: 1 | E39: 3 | F39: Accountability + Monitoring + Accuracy | G39: “We monitor AI systems in production” | H39: S. 3, Prinzip 3 Accountability, Accuracy & Proficiency | I39: hoch | J39: Monitoring in Produktion mit Outcome-Abgleich und User Feedback = prozessuale Operationalisierung | K39: =Tabelle5[[#This Row],[value_present]]*Tabelle5[[#This Row],[binding_level]] -> 3
A40: 3 | B40: 16 | C40: VAL_03 | D40: 1 | E40: 2 | F40: Transparenz explizit; User-notification als Transparenzregel | G40: “We openly communicate the purpose of our AI systems.”; “we inform customers whenever they interact directly with an AI system” | H40: S. 3, Prinzip 2 Transparency | I40: hoch | J40: Zweckoffenlegung und User-Information klar normiert | K40: =Tabelle5[[#This Row],[value_present]]*Tabelle5[[#This Row],[binding_level]] -> 2
...

Sheet 05_Governance_Coding
A1: company_id | B1: doc_id | C1: gov_id | D1: score_0_3 | E1: evidence_quote | F1: evidence_location | G1: why_not_higher | H1: coder_confidence | I1: notes
A2: 2 | B2: 8 | C2: GOV_01 | D2: 0 | H2: hoch | I2: Keine AI-spezifischen Rollen, Owner oder Gremien im KI-Abschnitt
A3: 2 | B3: 8 | C3: GOV_02 | D3: 1 | E3: “we prioritise an ethics by design approach to AI” | F3: S. 5, Our approach to Artificial Intelligence (AI) | G3: keine Schritte, Trigger, Verantwortlichen | H3: mittel | I3: Prozessabsicht/Ansatz („ethics by design“) erwähnt
A4: 2 | B4: 8 | C4: GOV_03 | D4: 0 | H4: hoch | I4: Keine AI-spezifischen Checks, Assessments oder Tools mit KI-Anker
A5: 2 | B5: 8 | C5: GOV_04 | D5: 0 | H5: hoch | I5: Keine AI-spezifischen Audit-/Assessment-Mechaniken
A6: 2 | B6: 8 | C6: GOV_05 | D6: 0 | H6: hoch | I6: Keine AI-spezifischen Trainings erwähnt
A7: 2 | B7: 8 | C7: GOV_06 | D7: 0 | H7: hoch | I7: Kein AI-spezifischer Eskalations- oder Incident-Prozess
A8: 2 | B8: 8 | C8: GOV_07 | D8: 0 | H8: hoch | I8: Kein AI-spezifisches Reporting, keine KPIs, keine Disclosure-Struktur
A9: 2 | B9: 9 | C9: GOV_01 | D9: 0 | H9: hoch | I9: Keine AI-spezifischen Rollen, Owner oder Gremien
A10: 2 | B10: 9 | C10: GOV_02 | D10: 2 | E10: “Regularly review artificial intelligence systems” | F10: S. 31, Digital Ethics | G10: keine Nachweise zu Frequenz, Outputs, Verantwortlichen oder Umsetzung | H10: mittel | I10: Regelmäßige Reviews von KI-Systemen sind dokumentiert
A11: 2 | B11: 9 | C11: GOV_03 | D11: 2 | E11: “Regularly review artificial intelligence systems to ensure fairness and prevent biases.” | F11: S. 31, Digital Ethics | G11: kein benanntes Tool, kein Nachweis der Implementierung | H11: mittel | I11: Fairness-/Bias-Review als dokumentierter Check
A12: 2 | B12: 9 | C12: GOV_04 | D12: 0 | H12: hoch | I12: Keine AI-spezifischen Audits oder Auditnachweise
A13: 2 | B13: 9 | C13: GOV_05 | D13: 0 | H13: hoch | I13: Keine AI-spezifischen Trainings
A14: 2 | B14: 9 | C14: GOV_06 | D14: 0 | H14: hoch | I14: Speak-Up-Kapitel ist allgemein, nicht KI-spezifisch
A15: 2 | B15: 9 | C15: GOV_07 | D15: 0 | H15: hoch | I15: Kein AI-spezifisches Reporting, keine KPIs, keine Reports
A16: 3 | B16: 16 | C16: GOV_01 | D16: 2 | E16: “established a Group Data and AI Trust Advisory Board (DAITAB)"; “establishes the new role of an AI Trust Officer” | F16: S. 5–6, DAITAB / Responsible AI Corporate Rules | G16: keine Wirksamkeitsnachweise, keine KPIs/Reports | H16: hoch | I16: Board, AI Trust Officers und Group AI Office sind klar benannt
A17: 3 | B17: 16 | C17: GOV_02 | D17: 2 | E17: "we consult relevant stakeholders – whether from the business, data science, IT”; “collectively establish the core principles and framework”; “extending privacy risk assessments to cover all RAI principles” | F17: S. 2; S. 6, RAI approach / Responsible AI Corporate Rules | G17: keine regelmäßigen Nachweisberichte oder auditierte Umsetzung | H17: hoch | I17: Cross-functional consultation, RAI framework, RAI-assessments dokumentiert
A18: 3 | B18: 16 | C18: GOV_03 | D18: 2 | E18: “perform a dedicated privacy risk assessment”; “extending privacy risk assessments to cover all RAI principles”; “monitor AI risks, conduct RAI-assessments with the CDO” | F18: S. 4; S. 6, Data Privacy / Responsible AI Corporate Rules | G18: keine Toolnamen, Templates oder Implementierungsbelege | H18: hoch | I18: Privacy risk assessment und RAI-assessments klar beschrieben
A19: 3 | B19: 16 | C19: GOV_04 | D19: 0 | H19: hoch | I19: Keine AI-spezifischen Audits oder Auditberichte
A20: 3 | B20: 16 | C20: GOV_05 | D20: 2 | E20: “strategically upskilling our workforce”; “providing operational guidance, technical support, AI literacy” | F20: S. 2; S. 6, RAI approach / Responsible AI Corporate Rules | G20: keine Frequenz, Coverage oder Trainingsnachweise | H20: hoch | I20: Upskilling und AI literacy dokumentiert
A21: 3 | B21: 16 | C21: GOV_06 | D21: 2 | E21: “supports Business Owners in incident management”; “escalate unresolved risk disagreements to the DAITAB” | F21: S. 6, Responsible AI Corporate Rules | G21: keine geübten Fälle, keine Nachweise zur Anwendung | H21: hoch | I21: Incident management und Eskalation an DAITAB explizit
A22: 3 | B22: 16 | C22: GOV_07 | D22: 0 | H22: hoch | I22: Kein AI-spezifisches Reporting, keine KPIs, keine regelmäßigen Reports
A23: 3 | B23: 17 | C23: GOV_01 | D23: 0 | H23: hoch | I23: Keine AI-spezifischen Rollen, Owner oder Gremien
A24: 3 | B24: 17 | C24: GOV_02 | D24: 0 | H24: hoch | I24: Keine AI-spezifischen Prozessschritte oder Abläufe
A25: 3 | B25: 17 | C25: GOV_03 | D25: 0 | H25: mittel | I25: Kontrollen werden nur für Datenqualität allgemein genannt; kein belastbarer AI-spezifischer Check
A26: 3 | B26: 17 | C26: GOV_04 | D26: 0 | H26: hoch | I26: Keine AI-spezifischen Audits
A27: 3 | B27: 17 | C27: GOV_05 | D27: 0 | H27: hoch | I27: Keine AI-spezifischen Trainings
A28: 3 | B28: 17 | C28: GOV_06 | D28: 0 | H28: hoch | I28: Allgemeine Speak-up-Regeln ohne KI-Anker
A29: 3 | B29: 17 | C29: GOV_07 | D29: 0 | H29: hoch | I29: Kein AI-spezifisches Reporting, keine KPIs, keine Reports
A30: 3 | B30: 18 | C30: GOV_01 | D30: 1 | E30: “establishment of our Data Advisory Board”; "elevate data ethics and selected data and analytics-related topics” | F30: S. 4, Data Ethics | G30: Board ist datenethisch breit, nicht eindeutig AI-spezifisch ausdifferenziert | H30: mittel | I30: Data Advisory Board mit Top-Management-Beteiligung genannt
A31: 3 | B31: 18 | C31: GOV_02 | D31: 2 | E31: “via the Privacy and Ethics Impact Assessment”; “risk-based approach to implementing the appropriate level of human involvement” | F31: S. 4, Data Ethics | G31: keine Nachweise zu Anwendungshäufigkeit, Outputs oder Regelvollzug | H31: hoch | I31: Risk-based human involvement und Privacy & Ethics Impact Assessment dokumentiert
A32: 3 | B32: 18 | C32: GOV_03 | D32: 2 | E32: “via the Privacy and Ethics Impact Assessment” | F32: S. 4, Data Ethics | G32: kein Implementierungsnachweis, keine Tooldetails | H32: hoch | I32: Privacy and Ethics Impact Assessment als konkreter Check
A33: 3 | B33: 18 | C33: GOV_04 | D33: 0 | H33: mittel | I33: Audits/Reviews werden im Dokument nur allgemein für Privacy-/Security-Management erwähnt, nicht hinreichend KI-spezifisch
A34: 3 | B34: 18 | C34: GOV_05 | D34: 2 | E34: “All relevant employees who develop or use AI solutions are trained” | F34: S. 4, Data Ethics | G34: keine Nachweise zu Frequenz, Coverage oder Abschlussquoten | H34: hoch | I34: Relevante Mitarbeitende mit AI-Bezug werden trainiert
A35: 3 | B35: 18 | C35: GOV_06 | D35: 0 | H35: hoch | I35: Kein KI-spezifischer Eskalations- oder Incident-Prozess
A36: 3 | B36: 18 | C36: GOV_07 | D36: 0 | H36: hoch | I36: Kein KI-spezifisches Reporting, keine KPIs, keine Reports
A37: 3 | B37: 21 | C37: GOV_01 | D37: 1 | E37: “Within our sector frameworks”; “Board oversight and accountability” | F37: S. 3–4 | G37: keine klaren internen Rollen oder Verantwortlichen bei AllianzGI selbst | H37: mittel | I37: Sector frameworks und Board oversight werden erwähnt
A38: 3 | B38: 21 | C38: GOV_02 | D38: 2 | E38: “Board oversight and accountability”; “we perform a materiality assessment and prioritise the topic of responsible AI” | F38: S. 3, Our contribution | G38: keine Ablaufdetails, Frequenzen oder Umsetzungsnachweise | H38: mittel | I38: Materiality assessment und Priorisierung sind dokumentiert
A39: 3 | B39: 21 | C39: GOV_03 | D39: 1 | E39: “reported internally and externally” | F39: S. 4, Exhibit 3 | G39: nur Engagement-Fragen, kein interner implementierter Check | H39: niedrig | I39: Fehlerberichterstattung und Mechanismen werden als Prüffragen adressiert
A40: 3 | B40: 21 | C40: GOV_04 | D40: 0 | H40: hoch | I40: Keine internen AI-spezifischen Audits oder Auditnachweise
...

Sheet 07_Boundary_Cases
A1: case_id | B1: date | C1: company_id | D1: doc_id | E1: dimension(values/governance) | F1: value_id_or_gov_crit_id | G1: problem_description | H1: decision | I1: rule_added_to_codebook | J1: codebook_version
A2: C1 | B2: 02.03.26 | C2: 3 | D2: 16 | F2: VAL_06 (BIND) | G2: Reicht „privacy risk assessment whenever…“ als Standard/Prozessvorgabe (BIND=3) oder bleibt es Policy-Regel (BIND=2)? | H2: A: BIND=2 (deontisch „may only…“) B: BIND=3 (konkreter Pflicht-Check + Trigger). Gewählt: B, weil Check+Trigger explizit. | I2: nein | J2: V00.1
A3: C2 | B3: 02.03.26 | C3: 3 | D3: 16 | F3: VAL_09 | G3: Ist „monitor… ensure decisions match intended outcome“ ausreichend spezifisch für Technical Robustness & Reliability oder nur Accountability? | H3: A: VAL_09=1 (Reliability/Accuracy via Monitoring) B: VAL_09=0 (zu unspezifisch, eher VAL_02). Gewählt: A, aber konservativ mit BIND=1 und Confidence=mittel. | I3: ja | J3: V00.1
A4: C3 | B4: 02.03.26 | C4: 3 | D4: 16 | F4: GOV_02 | G4: Sind Stakeholder-Consultation + Corporate Rules bereits „dokumentierte Prozesse“ (Score=2) oder nur „benannt“ (Score=1)? | H4: A: Score=2 (Prozess-/Rahmen beschrieben) B: Score=1 (keine klare Prozesskette mit Trigger+Owner). Gewählt: B (konservativ). | I4: ja | J4: V00.1
A5: C4 | B5: 02.03.26 | C5: 3 | D5: 16 | F5: GOV_07 | G5: Zählt „provides recommendations to the Board“ als Reporting? | H5: A: Score=1/2 (Reporting-Struktur) B: Score=0 (keine KPI/Reportgegenstand+Frequenz). Gewählt: B, da Evidenzminimum für Reporting nicht erfüllt. | I5: nein | J5: V00.1
A6: C5 | B6: 02.03.26 | C6: 3 | D6: 16 | F6: VAL_15 | G6: Ist „Prohibited AI“ als ethische Leitplanke (VAL_15) zu werten, obwohl es nur als Gesetzesverstoß formuliert ist? | H6: A: VAL_15=1 (Guardrail/„do not“) B: VAL_15=0 (nur Compliance → VAL_14). Gewählt: B (konservativ). | I6: ja | J6: V00.1
A7: C6 | B7: 02.03.26 | C7: 3 | D7: 16 | F7: multiple | G7: Q&A enthält nur Fragen; mögliche Evidenz in (nicht sichtbaren) Antworten fehlt in der PDF. | H7: A: Codes evtl. aus Fragen ableiten B: Nur sichtbaren Text werten (Evidence-first). Gewählt: B. | I7: ja | J7: V00.1
A8: C7 | B8: 02.03.26 | C8: 4 | D8: 22 | F8: VAL_04 vs VAL_03 | G8: Ist „comprehensible decision-making processes“ Explainability (VAL_04) oder nur Transparenz (VAL_03)? | H8: A: VAL_04=0 (nur Transparenz) B: VAL_04=1 (Erklär-/Interpretierkomponente). Gewählt: B (konservativ BIND=1, Confidence=mittel), da „decision-making… comprehensible“ über reines Disclosure hinausgeht. | I8: ja | J8: V00.1
A9: C8 | B9: 02.03.26 | C9: 4 | D9: 22 | F9: VAL_14 (BIND) | G9: Erhöht „central inventory + assessments“ die Bindigkeit für Compliance auf BIND=3 (Prozessvorgabe) oder bleibt BIND=2 (Policy-Regel/Verbot)? | H9: A: BIND=2 (starkes Verbot, aber Prozess unkonkret) B: BIND=3 (Operationalisierung via Inventory/Assessments). Gewählt: A, weil Assessments nicht spezifiziert (keine definierten Kontrollschritte). | I9: ja | J9: V00.1
A10: C9 | B10: 02.03.26 | C10: 4 | D10: 22 | F10: GOV_02 / GOV_03 | G10: Sind Inventory/Assessments bereits „dokumentiert“ (Score=2) oder nur „benannt“ (Score=1)? | H10: A: Score=2 (konkretes Tool/Prozess genannt) B: Score=1 (ohne Trigger/Owner/Details). Gewählt: B (konservativ). | I10: ja | J10: V00.1
A11: C10 | B11: 02.03.26 | C11: 4 | D11: 22 | F11: VAL_16 | G11: Reicht „focus on strong data and AI governance“ für VAL_16 oder ist es zu allgemein? | H11: A: VAL_16=1 (Data Governance explizit im KI-Kontext) B: VAL_16=0 (zu unspezifisch, keine Mechanik). Gewählt: A (BIND=1, Confidence=mittel) wegen explizitem Governance-Bezug. | I11: ja | J11: V00.1
A12: C11 | B12: 02.03.26 | C12: 4 | D12: 22 | F12: VAL_08 | G12: Ist „well-being and safety“/„Robust & Safe“ ausreichend für VAL_08 (Safety & Harm Prevention) oder nur Robustness (VAL_09)? | H12: A: VAL_08=1 (Safety explizit) B: VAL_08=0 (keine Harm-Controls). Gewählt: A mit Confidence=mittel, da „safety“ wörtlich genannt. | I12: ja | J12: V00.1
A13: C12 | B13: 02.03.26 | C13: 4 | D13: 22 | F13: VAL_18 | G13: Zählt Privacy als „essential human right“ bereits als Human Rights (VAL_18) oder bleibt es nur VAL_06? | H13: A: VAL_18=1 (human right explizit + HR policy) B: VAL_18=0 (nur Datenschutzwert). Gewählt: A (Confidence=mittel) wegen HR policy + „human right“-Formulierung. | I13: nein | J13: V00.1
... A370: C368 | B370: 18.02.2026 | C370: 40 | D370: 239 | F370: VAL_13 / VAL_01 / VAL_03 | G370: Kund*innennutzen ist genannt, aber der KI-Anker bleibt indirekter als bei Bias-/ML-Passagen. | H370: A: VAL_13=1. B: VAL_13=0. Gewählt: B, konservativ, da die Passage zwar anschlussfähig ist, aber keinen gleich starken KI-/ML-Anker wie andere Evidenzen besitzt. | I370: nein | J370: V1

Sheet 03b_Values_Company_Level
A1: company_id | B1: value_id | C1: value_present_company | D1: binding_level_company | E1: value_points_company | F1: doc_id_strongest | G1: evidence_location_strongest | H1: evidence_quote_strongest
A2: 1 | B2: VAL_01 | C2: =IF(Tabelle18[[#This Row],[binding_level_company]]>=1,1,0) -> 0 | D2: =IFERROR(_xlfn.MAXIFS(Tabelle5[binding_level],Tabelle5[company_id],Tabelle18[[#This Row],[company_id]],Tabelle5[value_id],Tabelle18[[#This Row],[value_id]],Tabelle5[value_present],1),0) -> 0 | E2: =IFERROR(_xlfn.MAXIFS(Tabelle5[value_points],Tabelle5[company_id],Tabelle18[[#This Row],[company_id]],Tabelle5[value_id],Tabelle18[[#This Row],[value_id]]),0) -> 0 | F2: =IF(Tabelle18[[#This Row],[value_points_company]]=0,"",IFERROR(_xlfn.MINIFS(Tabelle5[doc_id],Tabelle5[company_id],Tabelle18[[#This Row],[company_id]],Tabelle5[value_id],Tabelle18[[#This Row],[value_id]],Tabelle5[value_points],Tabelle18[[#This Row],[value_points_company]]),"")) | G2: {=IF(Tabelle18[[#This Row],[doc_id_strongest]]="","",IFERROR(INDEX(Tabelle5[evidence_location],MATCH(1,(Tabelle5[company_id]=Tabelle18[[#This Row],[company_id]])*(Tabelle5[value_id]=Tabelle18[[#This Row],[value_id]])*(Tabelle5[doc_id]=Tabelle18[[#This Row],[doc_id_strongest]]),0)),""))} | H2: {=IF(Tabelle18[[#This Row],[doc_id_strongest]]="","",IFERROR(INDEX(Tabelle5[evidence_quote],MATCH(1,(Tabelle5[company_id]=Tabelle18[[#This Row],[company_id]])*(Tabelle5[value_id]=Tabelle18[[#This Row],[value_id]])*(Tabelle5[doc_id]=Tabelle18[[#This Row],[doc_id_strongest]]),0)),""))}
A3: 1 | B3: VAL_02 | C3: =IF(Tabelle18[[#This Row],[binding_level_company]]>=1,1,0) -> 0 | D3: =IFERROR(_xlfn.MAXIFS(Tabelle5[binding_level],Tabelle5[company_id],Tabelle18[[#This Row],[company_id]],Tabelle5[value_id],Tabelle18[[#This Row],[value_id]],Tabelle5[value_present],1),0) -> 0 | E3: =IFERROR(_xlfn.MAXIFS(Tabelle5[value_points],Tabelle5[company_id],Tabelle18[[#This Row],[company_id]],Tabelle5[value_id],Tabelle18[[#This Row],[value_id]]),0) -> 0 | F3: =IF(Tabelle18[[#This Row],[value_points_company]]=0,"",IFERROR(_xlfn.MINIFS(Tabelle5[doc_id],Tabelle5[company_id],Tabelle18[[#This Row],[company_id]],Tabelle5[value_id],Tabelle18[[#This Row],[value_id]],Tabelle5[value_points],Tabelle18[[#This Row],[value_points_company]]),"")) | G3: {=IF(Tabelle18[[#This Row],[doc_id_strongest]]="","",IFERROR(INDEX(Tabelle5[evidence_location],MATCH(1,(Tabelle5[company_id]=Tabelle18[[#This Row],[company_id]])*(Tabelle5[value_id]=Tabelle18[[#This Row],[value_id]])*(Tabelle5[doc_id]=Tabelle18[[#This Row],[doc_id_strongest]]),0)),""))} | H3: {=IF(Tabelle18[[#This Row],[doc_id_strongest]]="","",IFERROR(INDEX(Tabelle5[evidence_quote],MATCH(1,(Tabelle5[company_id]=Tabelle18[[#This Row],[company_id]])*(Tabelle5[value_id]=Tabelle18[[#This Row],[value_id]])*(Tabelle5[doc_id]=Tabelle18[[#This Row],[doc_id_strongest]]),0)),""))}
A4: 1 | B4: VAL_03 | C4: =IF(Tabelle18[[#This Row],[binding_level_company]]>=1,1,0) -> 0 | D4: =IFERROR(_xlfn.MAXIFS(Tabelle5[binding_level],Tabelle5[company_id],Tabelle18[[#This Row],[company_id]],Tabelle5[value_id],Tabelle18[[#This Row],[value_id]],Tabelle5[value_present],1),0) -> 0 | E4: =IFERROR(_xlfn.MAXIFS(Tabelle5[value_points],Tabelle5[company_id],Tabelle18[[#This Row],[company_id]],Tabelle5[value_id],Tabelle18[[#This Row],[value_id]]),0) -> 0 | F4: =IF(Tabelle18[[#This Row],[value_points_company]]=0,"",IFERROR(_xlfn.MINIFS(Tabelle5[doc_id],Tabelle5[company_id],Tabelle18[[#This Row],[company_id]],Tabelle5[value_id],Tabelle18[[#This Row],[value_id]],Tabelle5[value_points],Tabelle18[[#This Row],[value_points_company]]),"")) | G4: {=IF(Tabelle18[[#This Row],[doc_id_strongest]]="","",IFERROR(INDEX(Tabelle5[evidence_location],MATCH(1,(Tabelle5[company_id]=Tabelle18[[#This Row],[company_id]])*(Tabelle5[value_id]=Tabelle18[[#This Row],[value_id]])*(Tabelle5[doc_id]=Tabelle18[[#This Row],[doc_id_strongest]]),0)),""))} | H4: {=IF(Tabelle18[[#This Row],[doc_id_strongest]]="","",IFERROR(INDEX(Tabelle5[evidence_quote],MATCH(1,(Tabelle5[company_id]=Tabelle18[[#This Row],[company_id]])*(Tabelle5[value_id]=Tabelle18[[#This Row],[value_id]])*(Tabelle5[doc_id]=Tabelle18[[#This Row],[doc_id_strongest]]),0)),""))}
A5: 1 | B5: VAL_04 | C5: =IF(Tabelle18[[#This Row],[binding_level_company]]>=1,1,0) -> 0 | D5: =IFERROR(_xlfn.MAXIFS(Tabelle5[binding_level],Tabelle5[company_id],Tabelle18[[#This Row],[company_id]],Tabelle5[value_id],Tabelle18[[#This Row],[value_id]],Tabelle5[value_present],1),0) -> 0 | E5: =IFERROR(_xlfn.MAXIFS(Tabelle5[value_points],Tabelle5[company_id],Tabelle18[[#This Row],[company_id]],Tabelle5[value_id],Tabelle18[[#This Row],[value_id]]),0) -> 0 | F5: =IF(Tabelle18[[#This Row],[value_points_company]]=0,"",IFERROR(_xlfn.MINIFS(Tabelle5[doc_id],Tabelle5[company_id],Tabelle18[[#This Row],[company_id]],Tabelle5[value_id],Tabelle18[[#This Row],[value_id]],Tabelle5[value_points],Tabelle18[[#This Row],[value_points_company]]),"")) | G5: {=IF(Tabelle18[[#This Row],[doc_id_strongest]]="","",IFERROR(INDEX(Tabelle5[evidence_location],MATCH(1,(Tabelle5[company_id]=Tabelle18[[#This Row],[company_id]])*(Tabelle5[value_id]=Tabelle18[[#This Row],[value_id]])*(Tabelle5[doc_id]=Tabelle18[[#This Row],[doc_id_strongest]]),0)),""))} | H5: {=IF(Tabelle18[[#This Row],[doc_id_strongest]]="","",IFERROR(INDEX(Tabelle5[evidence_quote],MATCH(1,(Tabelle5[company_id]=Tabelle18[[#This Row],[company_id]])*(Tabelle5[value_id]=Tabelle18[[#This Row],[value_id]])*(Tabelle5[doc_id]=Tabelle18[[#This Row],[doc_id_strongest]]),0)),""))}
A6: 1 | B6: VAL_05 | C6: =IF(Tabelle18[[#This Row],[binding_level_company]]>=1,1,0) -> 0 | D6: =IFERROR(_xlfn.MAXIFS(Tabelle5[binding_level],Tabelle5[company_id],Tabelle18[[#This Row],[company_id]],Tabelle5[value_id],Tabelle18[[#This Row],[value_id]],Tabelle5[value_present],1),0) -> 0 | E6: =IFERROR(_xlfn.MAXIFS(Tabelle5[value_points],Tabelle5[company_id],Tabelle18[[#This Row],[company_id]],Tabelle5[value_id],Tabelle18[[#This Row],[value_id]]),0) -> 0 | F6: =IF(Tabelle18[[#This Row],[value_points_company]]=0,"",IFERROR(_xlfn.MINIFS(Tabelle5[doc_id],Tabelle5[company_id],Tabelle18[[#This Row],[company_id]],Tabelle5[value_id],Tabelle18[[#This Row],[value_id]],Tabelle5[value_points],Tabelle18[[#This Row],[value_points_company]]),"")) | G6: {=IF(Tabelle18[[#This Row],[doc_id_strongest]]="","",IFERROR(INDEX(Tabelle5[evidence_location],MATCH(1,(Tabelle5[company_id]=Tabelle18[[#This Row],[company_id]])*(Tabelle5[value_id]=Tabelle18[[#This Row],[value_id]])*(Tabelle5[doc_id]=Tabelle18[[#This Row],[doc_id_strongest]]),0)),""))} | H6: {=IF(Tabelle18[[#This Row],[doc_id_strongest]]="","",IFERROR(INDEX(Tabelle5[evidence_quote],MATCH(1,(Tabelle5[company_id]=Tabelle18[[#This Row],[company_id]])*(Tabelle5[value_id]=Tabelle18[[#This Row],[value_id]])*(Tabelle5[doc_id]=Tabelle18[[#This Row],[doc_id_strongest]]),0)),""))}
